#VRML_SIM R2023b utf8

EXTERNPROTO "https://raw.githubusercontent.com/cyberbotics/webots/R2023b/projects/objects/backgrounds/protos/TexturedBackground.proto"
EXTERNPROTO "https://raw.githubusercontent.com/cyberbotics/webots/R2023b/projects/objects/backgrounds/protos/TexturedBackgroundLight.proto"
EXTERNPROTO "https://raw.githubusercontent.com/cyberbotics/webots/R2023b/projects/objects/floors/protos/RectangleArena.proto"
EXTERNPROTO "https://raw.githubusercontent.com/cyberbotics/webots/R2023b/projects/appearances/protos/Parquetry.proto"

WorldInfo {
}
Viewpoint {
  orientation 0.38806751982375265 0.34507272000347367 -0.8545925449986359 1.9888216302056263
  position 0.12033754125698827 0.737115941700868 0.9070022691224352
  follow "Hexapod"
}
TexturedBackground {
}
RectangleArena {
  floorSize 10 10
  floorAppearance Parquetry {
    type "light strip"
  }
}
TexturedBackgroundLight {
}
Pose {
  translation -0.83 0 0
  children [
    Group {
      children [
        Solid {
          translation -0.019933880692263206 -0.03998729742886506 0.04960760000000001
          rotation 1.0258372560765865e-12 4.305264972574162e-13 -0.9999999999999999 5.0763256632347156e-05
          children [
            DEF BOX Shape {
              appearance PBRAppearance {
              }
              geometry Box {
                size 0.1 0.1 0.1
              }
            }
          ]
          boundingObject USE BOX
          physics Physics {
          }
          linearVelocity -5.2162031489795994e-17 4.759384818214922e-17 -5.6843418860808e-17
          angularVelocity -1.0658141036401518e-15 -7.993605777301121e-16 -2.6936724930001772e-17
        }
        Solid {
          translation 0.06990678014426754 -0.19993550478438063 0.0496076
          rotation 7.655079468438149e-13 -3.737492956399856e-13 1 9.931916513728612e-05
          children [
            DEF BOX Shape {
              appearance PBRAppearance {
              }
              geometry Box {
                size 0.1 0.1 0.1
              }
            }
          ]
          name "solid(1)"
          boundingObject USE BOX
          physics Physics {
          }
          linearVelocity 4.6346923497183124e-17 -2.4574112851578927e-17 5.6843418860808e-17
          angularVelocity -2.664535259100378e-16 7.993605777301126e-16 -2.780858345347146e-16
        }
        Solid {
          translation 0.2427788537707931 -0.1300340540610465 0.04960760000000001
          rotation -9.364176988186379e-14 2.4291477418732763e-14 -1 2.4836538398187308e-05
          children [
            DEF BOX Shape {
              appearance PBRAppearance {
              }
              geometry Box {
                size 0.1 0.1 0.1
              }
            }
          ]
          name "solid(2)"
          boundingObject USE BOX
          physics Physics {
          }
          linearVelocity -4.151239227910184e-17 2.537400585270245e-17 0
          angularVelocity -2.6645352591003717e-16 -7.993605777301118e-16 5.660295665242386e-17
        }
        Solid {
          translation 0.24010227170996068 0.2200350097607885 0.0496076
          rotation -1.4293807415136307e-12 -2.758760940529022e-13 1 7.175482358369224e-05
          children [
            DEF BOX Shape {
              appearance PBRAppearance {
              }
              geometry Box {
                size 0.1 0.1 0.1
              }
            }
          ]
          name "solid(3)"
          boundingObject USE BOX
          physics Physics {
          }
          linearVelocity -4.895529094006009e-17 5.825162083271598e-17 5.6843418860808e-17
          angularVelocity -1.065814103640151e-15 -5.329070518200744e-16 -4.409552260002746e-17
        }
        Solid {
          translation -0.020051649108723035 0.15992621635509713 0.0496076
          rotation 9.369474074918168e-14 -7.192364067712405e-14 -1 0.00017334433090602426
          children [
            DEF BOX Shape {
              appearance PBRAppearance {
              }
              geometry Box {
                size 0.1 0.1 0.1
              }
            }
          ]
          name "solid(4)"
          boundingObject USE BOX
          physics Physics {
          }
          linearVelocity -2.3416683850934195e-17 -7.052561032042326e-18 -5.6843418860808e-17
          angularVelocity 5.329070518200744e-16 -5.32907051820074e-16 -9.51664589378108e-18
        }
        Solid {
          translation 0.23263016943535741 0.05998653481257025 0.04960760000000001
          rotation -4.866852205371245e-12 3.832715642663069e-12 -1 2.886579514978557e-05
          children [
            DEF BOX Shape {
              appearance PBRAppearance {
              }
              geometry Box {
                size 0.1 0.1 0.1
              }
            }
          ]
          name "solid(5)"
          boundingObject USE BOX
          physics Physics {
          }
          linearVelocity 1.6821256153795729e-18 6.00728587228863e-17 5.684341886080802e-17
          angularVelocity -1.5987211554602233e-15 -2.66453525910037e-16 1.0287040965343364e-16
        }
      ]
    }
  ]
}
Robot {
  translation 0.0007851898605055415 -1.939539803513723e-05 0.10845436622157492
  rotation 1 0 0 0
  children [
    DEF Leg0FR Pose {
      translation 0.063 0.082 0
      rotation 0 0 1 0.785398
      children [
        DEF JointBC Pose {
          translation -0.008 0 0
          children [
            Shape {
              appearance PBRAppearance {
                baseColor 0.101961 0.101961 0.101961
                roughness 1
                metalness 0.3
              }
              geometry Box {
                size 0.045 0.02 0.045
              }
            }
          ]
        }
        HingeJoint {
          jointParameters HingeJointParameters {
            position 2.060248409161821e-06
            axis 0 0 -1
          }
          device [
            PositionSensor {
              name "S_FR_COXA"
            }
            RotationalMotor {
              name "M_FR_COXA"
            }
          ]
          endPoint Solid {
            translation 0.019999995879460743 -0.0020000412049639396 0
            rotation 0 0 -1 2.0602438369637884e-06
            children [
              DEF JointCF Pose {
                translation 0.022 -1.67293e-08 -1.67294e-08
                rotation 0.5773509358554485 -0.5773509358554485 0.5773489358556708 2.0944
                children [
                  Shape {
                    appearance PBRAppearance {
                      baseColor 0.101961 0.101961 0.101961
                      roughness 1
                      metalness 0.3
                    }
                    geometry Box {
                      size 0.045 0.02 0.045
                    }
                  }
                ]
              }
              DEF R_SHAPE_COXA Shape {
                appearance PBRAppearance {
                  baseColor 0.54902 0.54902 0.54902
                  roughness 1
                  metalness 0.3
                }
                geometry Mesh {
                  url [
                    "../webotsSTL/right-coxa-webots.stl"
                  ]
                }
              }
              HingeJoint {
                jointParameters HingeJointParameters {
                  position 1.2982363794498855e-06
                  axis 0 -1 0
                  anchor 0.0229 0 -0.0077
                }
                device [
                  RotationalMotor {
                    name "M_FR_FEMUR"
                  }
                  PositionSensor {
                    name "S_FR_FEMUR"
                  }
                ]
                endPoint Solid {
                  translation 0.06299999000354589 0 5.2059272331352047e-08
                  rotation -0.9999999999998743 -4.2960885157605303e-07 -2.5833918972493605e-07 1.5707953071798226
                  children [
                    HingeJoint {
                      jointParameters HingeJointParameters {
                        position -5.996856018317297e-07
                        axis 0 0 1
                        anchor 0.041 0.008 0
                      }
                      device [
                        RotationalMotor {
                          name "M_FR_TIBIA"
                        }
                        PositionSensor {
                          name "S_FR_TIBIA"
                        }
                      ]
                      endPoint Solid {
                        translation 0.056028876377227324 0.04795757928394432 2.476705097336627e-05
                        rotation -2.0863081623328384e-07 -0.7071082811857372 0.7071052811841453 3.1415895759591437
                        children [
                          DEF JointFT Pose {
                            translation 0.0118 0 0.035
                            rotation 0.3243588663662829 0.3243588663662829 0.888584633908982 1.68865
                            children [
                              Shape {
                                appearance PBRAppearance {
                                  baseColor 0.101961 0.101961 0.101961
                                  roughness 1
                                  metalness 0.3
                                }
                                geometry Box {
                                  size 0.045 0.02 0.045
                                }
                              }
                            ]
                          }
                          DEF R_SHAPE_TIBIA Shape {
                            appearance PBRAppearance {
                              baseColor 0.513726 0.513726 0.513726
                              roughness 1
                              metalness 0.3
                            }
                            geometry Mesh {
                              url [
                                "../webotsSTL/right-tibia-webots.stl"
                              ]
                            }
                          }
                        ]
                        boundingObject Group {
                          children [
                            Pose {
                              translation -0.033 0 -0.02
                              children [
                                Box {
                                  size 0.01 0.01 0.08
                                }
                              ]
                            }
                          ]
                        }
                        physics Physics {
                          density -1
                          mass 0.8
                        }
                      }
                    }
                    DEF R_SHAPE_FEMUR Shape {
                      appearance PBRAppearance {
                        baseColor 0.505882 0.505882 0.505882
                        roughness 1
                        metalness 0.3
                      }
                      geometry Mesh {
                        url [
                          "../webotsSTL/right-femur-webots.stl"
                        ]
                      }
                    }
                  ]
                  boundingObject USE R_SHAPE_FEMUR
                  physics Physics {
                    density -1
                    mass 0.8
                  }
                }
              }
            ]
            name "solid(5)"
            boundingObject USE R_SHAPE_COXA
            physics Physics {
              density -1
              mass 0.8
            }
          }
        }
      ]
    }
    DEF Leg0BR Pose {
      translation 0.06 -0.08 0
      rotation 0 0 1 -0.785395307179586
      children [
        DEF JointBC Pose {
          translation -0.008 0 0
          children [
            Shape {
              appearance PBRAppearance {
                baseColor 0.101961 0.101961 0.101961
                roughness 1
                metalness 0.3
              }
              geometry Box {
                size 0.045 0.02 0.045
              }
            }
          ]
        }
        HingeJoint {
          jointParameters HingeJointParameters {
            position -1.8461297754271597e-06
            axis 0 0 -1
          }
          device [
            PositionSensor {
              name "S_BR_COXA"
            }
            RotationalMotor {
              name "M_BR_COXA"
            }
          ]
          endPoint Solid {
            translation 0.020000003692225467 -0.0019999630774010834 0
            rotation 0 0 1 1.8460608322559748e-06
            children [
              DEF JointCF Pose {
                translation 0.022 -1.67293e-08 -1.67294e-08
                rotation 0.5773509358554485 -0.5773509358554485 0.5773489358556708 2.0944
                children [
                  Shape {
                    appearance PBRAppearance {
                      baseColor 0.101961 0.101961 0.101961
                      roughness 1
                      metalness 0.3
                    }
                    geometry Box {
                      size 0.045 0.02 0.045
                    }
                  }
                ]
              }
              DEF R_SHAPE_COXA Shape {
                appearance PBRAppearance {
                  baseColor 0.54902 0.54902 0.54902
                  roughness 1
                  metalness 0.3
                }
                geometry Mesh {
                  url [
                    "../webotsSTL/right-coxa-webots.stl"
                  ]
                }
              }
              HingeJoint {
                jointParameters HingeJointParameters {
                  position 1.1474390656919117e-06
                  axis 0 -1 0
                  anchor 0.0229 0 -0.0077
                }
                device [
                  RotationalMotor {
                    name "M_BR_FEMUR"
                  }
                  PositionSensor {
                    name "S_BR_FEMUR"
                  }
                ]
                endPoint Solid {
                  translation 0.06299999116469261 0 4.6012301470679806e-08
                  rotation -0.9999999999999205 -3.542101178194288e-07 -1.8294053284596335e-07 1.570795307179764
                  children [
                    HingeJoint {
                      jointParameters HingeJointParameters {
                        position -5.505027698949234e-07
                        axis 0 0 1
                        anchor 0.041 0.008 0
                      }
                      device [
                        RotationalMotor {
                          name "M_BR_TIBIA"
                        }
                        PositionSensor {
                          name "S_BR_TIBIA"
                        }
                      ]
                      endPoint Solid {
                        translation 0.0560288744120004 0.04795758002310701 2.476705097336627e-05
                        rotation -1.9124202235593766e-07 -0.7071082811857232 0.7071052811841642 3.141589610736584
                        children [
                          DEF JointFT Pose {
                            translation 0.0118 0 0.035
                            rotation 0.3243588663662829 0.3243588663662829 0.888584633908982 1.68865
                            children [
                              Shape {
                                appearance PBRAppearance {
                                  baseColor 0.101961 0.101961 0.101961
                                  roughness 1
                                  metalness 0.3
                                }
                                geometry Box {
                                  size 0.045 0.02 0.045
                                }
                              }
                            ]
                          }
                          DEF R_SHAPE_TIBIA Shape {
                            appearance PBRAppearance {
                              baseColor 0.513726 0.513726 0.513726
                              roughness 1
                              metalness 0.3
                            }
                            geometry Mesh {
                              url [
                                "../webotsSTL/right-tibia-webots.stl"
                              ]
                            }
                          }
                        ]
                        boundingObject Group {
                          children [
                            Pose {
                              translation -0.033 0 -0.02
                              children [
                                Box {
                                  size 0.01 0.01 0.08
                                }
                              ]
                            }
                          ]
                        }
                        physics Physics {
                          density -1
                          mass 0.8
                        }
                      }
                    }
                    DEF R_SHAPE_FEMUR Shape {
                      appearance PBRAppearance {
                        baseColor 0.505882 0.505882 0.505882
                        roughness 1
                        metalness 0.3
                      }
                      geometry Mesh {
                        url [
                          "../webotsSTL/right-femur-webots.stl"
                        ]
                      }
                    }
                  ]
                  boundingObject USE R_SHAPE_FEMUR
                  physics Physics {
                    density -1
                    mass 0.8
                  }
                }
              }
            ]
            name "solid(4)"
            boundingObject USE R_SHAPE_COXA
            physics Physics {
              density -1
              mass 0.8
            }
          }
        }
      ]
    }
    DEF Leg0FL Pose {
      translation -0.063 0.082 0
      rotation 0 0 1 2.3562
      children [
        DEF JointBC Pose {
          translation -0.008 0 0
          children [
            Shape {
              appearance PBRAppearance {
                baseColor 0.101961 0.101961 0.101961
                roughness 1
                metalness 0.3
              }
              geometry Box {
                size 0.045 0.02 0.045
              }
            }
          ]
        }
        HingeJoint {
          jointParameters HingeJointParameters {
            position 4.444349040465791e-06
            axis 0 0 -1
          }
          device [
            PositionSensor {
              name "S_FL_COXA"
            }
            RotationalMotor {
              name "M_FL_COXA"
            }
          ]
          endPoint Solid {
            translation 0.020000009054553014 0.0019999094523997156 0
            rotation 0 0 -1 4.444344707121536e-06
            children [
              DEF JointCF Pose {
                translation 0.022 -1.67293e-08 -1.67294e-08
                rotation 0.5773509358554485 -0.5773509358554485 0.5773489358556708 2.0944
                children [
                  Shape {
                    appearance PBRAppearance {
                      baseColor 0.101961 0.101961 0.101961
                      roughness 1
                      metalness 0.3
                    }
                    geometry Box {
                      size 0.045 0.02 0.045
                    }
                  }
                ]
              }
              DEF L_SHAPE_COXA Shape {
                appearance PBRAppearance {
                  baseColor 0.54902 0.54902 0.54902
                  roughness 1
                  metalness 0.3
                }
                geometry Mesh {
                  url [
                    "../webotsSTL/left-coxa-webots.stl"
                  ]
                }
              }
              HingeJoint {
                jointParameters HingeJointParameters {
                  position -2.3529317857499633e-06
                  axis 0 1 0
                  anchor 0.0229 0 -0.0077
                }
                device [
                  RotationalMotor {
                    name "M_FL_FEMUR"
                  }
                  PositionSensor {
                    name "S_FL_FEMUR"
                  }
                ]
                endPoint Solid {
                  translation 0.06299998188231401 0 9.43525433122136e-08
                  rotation 0.999999999998616 -1.1764615716186965e-06 1.1764658929131486e-06 1.570800000001382
                  children [
                    HingeJoint {
                      jointParameters HingeJointParameters {
                        position 1.114670396614138e-06
                        axis 0 0 1
                        anchor 0.04 -0.0095 0
                      }
                      device [
                        RotationalMotor {
                          name "M_FL_TIBIA"
                        }
                        PositionSensor {
                          name "S_FL_TIBIA"
                        }
                      ]
                      endPoint Solid {
                        translation 0.06100004625880841 -0.05099997659189581 -8.485299999999979e-07
                        rotation -3.974857207971298e-07 0.7071062811857454 0.7071072811868845 3.1415907881915532
                        children [
                          DEF JointFT Pose {
                            translation 0.012 0 0.0354013
                            rotation 0.3243588663662829 0.3243588663662829 0.888584633908982 1.68865
                            children [
                              Shape {
                                appearance PBRAppearance {
                                  baseColor 0.101961 0.101961 0.101961
                                  roughness 1
                                  metalness 0.3
                                }
                                geometry Box {
                                  size 0.045 0.02 0.045
                                }
                              }
                            ]
                          }
                          DEF L_SHAPE_TIBIA Shape {
                            appearance PBRAppearance {
                              baseColor 0.513726 0.513726 0.513726
                              roughness 1
                              metalness 0.3
                            }
                            geometry Mesh {
                              url [
                                "../webotsSTL/left-tibia-webots.stl"
                              ]
                            }
                          }
                        ]
                        boundingObject Group {
                          children [
                            Pose {
                              translation -0.033 0 -0.02
                              children [
                                Box {
                                  size 0.01 0.01 0.08
                                }
                              ]
                            }
                          ]
                        }
                        physics Physics {
                          density -1
                          mass 0.8
                        }
                      }
                    }
                    DEF L_SHAPE_FEMUR Shape {
                      appearance PBRAppearance {
                        baseColor 0.505882 0.505882 0.505882
                        roughness 1
                        metalness 0.3
                      }
                      geometry Mesh {
                        url [
                          "../webotsSTL/left-femur-webots.stl"
                        ]
                      }
                    }
                  ]
                  boundingObject USE L_SHAPE_FEMUR
                  physics Physics {
                    density -1
                    mass 0.8
                  }
                }
              }
            ]
            name "solid(2)"
            boundingObject USE L_SHAPE_COXA
            physics Physics {
              density -1
              mass 0.8
            }
          }
        }
      ]
    }
    DEF Leg0BL Pose {
      translation -0.06 -0.08 0
      rotation 0 0 -1 2.35619
      children [
        DEF JointBC Pose {
          translation -0.008 0 0
          children [
            Shape {
              appearance PBRAppearance {
                baseColor 0.101961 0.101961 0.101961
                roughness 1
                metalness 0.3
              }
              geometry Box {
                size 0.045 0.02 0.045
              }
            }
          ]
        }
        HingeJoint {
          jointParameters HingeJointParameters {
            position 4.6915355662886235e-06
            axis 0 0 -1
          }
          device [
            PositionSensor {
              name "S_BL_COXA"
            }
            RotationalMotor {
              name "M_BL_COXA"
            }
          ]
          endPoint Solid {
            translation 0.020000009548903068 0.001999904508666899 0
            rotation 0 0 -1 4.691570909303045e-06
            children [
              DEF JointCF Pose {
                translation 0.022 -1.67293e-08 -1.67294e-08
                rotation 0.5773509358554485 -0.5773509358554485 0.5773489358556708 2.0944
                children [
                  Shape {
                    appearance PBRAppearance {
                      baseColor 0.101961 0.101961 0.101961
                      roughness 1
                      metalness 0.3
                    }
                    geometry Box {
                      size 0.045 0.02 0.045
                    }
                  }
                ]
              }
              DEF L_SHAPE_COXA Shape {
                appearance PBRAppearance {
                  baseColor 0.54902 0.54902 0.54902
                  roughness 1
                  metalness 0.3
                }
                geometry Mesh {
                  url [
                    "../webotsSTL/left-coxa-webots.stl"
                  ]
                }
              }
              HingeJoint {
                jointParameters HingeJointParameters {
                  position -2.507762471033202e-06
                  axis 0 1 0
                  anchor 0.0229 0 -0.0077
                }
                device [
                  RotationalMotor {
                    name "M_BL_FEMUR"
                  }
                  PositionSensor {
                    name "S_BL_FEMUR"
                  }
                ]
                endPoint Solid {
                  translation 0.06299998069010265 0 1.0056125089585866e-07
                  rotation 0.9999999999984278 -1.2538766298981776e-06 1.253881235554539e-06 1.5708000000015705
                  children [
                    HingeJoint {
                      jointParameters HingeJointParameters {
                        position 1.152160030935532e-06
                        axis 0 0 1
                        anchor 0.04 -0.0095 0
                      }
                      device [
                        RotationalMotor {
                          name "M_BL_TIBIA"
                        }
                        PositionSensor {
                          name "S_BL_TIBIA"
                        }
                      ]
                      endPoint Solid {
                        translation 0.06100004781462731 -0.0509999758046117 -8.485299999999974e-07
                        rotation -4.10740298751132e-07 0.7071062811857292 0.7071072811868933 3.1415908147007467
                        children [
                          DEF JointFT Pose {
                            translation 0.012 0 0.0354013
                            rotation 0.3243588663662829 0.3243588663662829 0.888584633908982 1.68865
                            children [
                              Shape {
                                appearance PBRAppearance {
                                  baseColor 0.101961 0.101961 0.101961
                                  roughness 1
                                  metalness 0.3
                                }
                                geometry Box {
                                  size 0.045 0.02 0.045
                                }
                              }
                            ]
                          }
                          DEF L_SHAPE_TIBIA Shape {
                            appearance PBRAppearance {
                              baseColor 0.513726 0.513726 0.513726
                              roughness 1
                              metalness 0.3
                            }
                            geometry Mesh {
                              url [
                                "../webotsSTL/left-tibia-webots.stl"
                              ]
                            }
                          }
                        ]
                        boundingObject Group {
                          children [
                            Pose {
                              translation -0.033 0 -0.02
                              children [
                                Box {
                                  size 0.01 0.01 0.08
                                }
                              ]
                            }
                          ]
                        }
                        physics Physics {
                          density -1
                          mass 0.8
                        }
                      }
                    }
                    DEF L_SHAPE_FEMUR Shape {
                      appearance PBRAppearance {
                        baseColor 0.505882 0.505882 0.505882
                        roughness 1
                        metalness 0.3
                      }
                      geometry Mesh {
                        url [
                          "../webotsSTL/left-femur-webots.stl"
                        ]
                      }
                    }
                  ]
                  boundingObject USE L_SHAPE_FEMUR
                  physics Physics {
                    density -1
                    mass 0.8
                  }
                }
              }
            ]
            name "solid(1)"
            boundingObject USE L_SHAPE_COXA
            physics Physics {
              density -1
              mass 0.8
            }
          }
        }
      ]
    }
    DEF Leg0ML Pose {
      translation -0.08 0 0
      rotation 0 0 -1 3.14159
      children [
        DEF JointBC Pose {
          translation -0.008 0 0
          children [
            Shape {
              appearance PBRAppearance {
                baseColor 0.101961 0.101961 0.101961
                roughness 1
                metalness 0.3
              }
              geometry Box {
                size 0.045 0.02 0.045
              }
            }
          ]
        }
        HingeJoint {
          jointParameters HingeJointParameters {
            position 3.269903177861058e-10
            axis 0 0 -1
          }
          device [
            PositionSensor {
              name "S_ML_COXA"
            }
            RotationalMotor {
              name "M_ML_COXA"
            }
          ]
          endPoint Solid {
            translation 0.02000000016671381 0.0019999983328612076 0
            rotation 0 0 -1 0
            children [
              DEF JointCF Pose {
                translation 0.022 -1.67293e-08 -1.67294e-08
                rotation 0.5773509358554485 -0.5773509358554485 0.5773489358556708 2.0944
                children [
                  Shape {
                    appearance PBRAppearance {
                      baseColor 0.101961 0.101961 0.101961
                      roughness 1
                      metalness 0.3
                    }
                    geometry Box {
                      size 0.045 0.02 0.045
                    }
                  }
                ]
              }
              DEF L_SHAPE_COXA Shape {
                appearance PBRAppearance {
                  baseColor 0.54902 0.54902 0.54902
                  roughness 1
                  metalness 0.3
                }
                geometry Mesh {
                  url [
                    "../webotsSTL/left-coxa-webots.stl"
                  ]
                }
              }
              HingeJoint {
                jointParameters HingeJointParameters {
                  position -6.879355822454399e-07
                  axis 0 1 0
                  anchor 0.0229 0 -0.0077
                }
                device [
                  RotationalMotor {
                    name "M_ML_FEMUR"
                  }
                  PositionSensor {
                    name "S_ML_FEMUR"
                  }
                ]
                endPoint Solid {
                  translation 0.06299999470288627 0 2.7586215046657148e-08
                  rotation 0.9999999999998817 -3.43966527798151e-07 3.439677911619451e-07 1.5708000000001159
                  children [
                    HingeJoint {
                      jointParameters HingeJointParameters {
                        position 7.461986559192328e-07
                        axis 0 0 1
                        anchor 0.04 -0.0095 0
                      }
                      device [
                        RotationalMotor {
                          name "M_ML_TIBIA"
                        }
                        PositionSensor {
                          name "S_ML_TIBIA"
                        }
                      ]
                      endPoint Solid {
                        translation 0.061000030967238356 -0.05099998432981657 -8.485299999999974e-07
                        rotation -2.6721137965475223e-07 0.7071062811858986 0.7071072811867926 3.141590527642503
                        children [
                          DEF JointFT Pose {
                            translation 0.012 0 0.0354013
                            rotation 0.3243588663662829 0.3243588663662829 0.888584633908982 1.68865
                            children [
                              Shape {
                                appearance PBRAppearance {
                                  baseColor 0.101961 0.101961 0.101961
                                  roughness 1
                                  metalness 0.3
                                }
                                geometry Box {
                                  size 0.045 0.02 0.045
                                }
                              }
                            ]
                          }
                          DEF L_SHAPE_TIBIA Shape {
                            appearance PBRAppearance {
                              baseColor 0.513726 0.513726 0.513726
                              roughness 1
                              metalness 0.3
                            }
                            geometry Mesh {
                              url [
                                "../webotsSTL/left-tibia-webots.stl"
                              ]
                            }
                          }
                        ]
                        boundingObject Group {
                          children [
                            Pose {
                              translation -0.033 0 -0.02
                              children [
                                Box {
                                  size 0.01 0.01 0.08
                                }
                              ]
                            }
                          ]
                        }
                        physics Physics {
                          density -1
                          mass 0.8
                        }
                      }
                    }
                    DEF L_SHAPE_FEMUR Shape {
                      appearance PBRAppearance {
                        baseColor 0.505882 0.505882 0.505882
                        roughness 1
                        metalness 0.3
                      }
                      geometry Mesh {
                        url [
                          "../webotsSTL/left-femur-webots.stl"
                        ]
                      }
                    }
                  ]
                  boundingObject USE L_SHAPE_FEMUR
                  physics Physics {
                    density -1
                    mass 0.8
                  }
                }
              }
            ]
            name "solid(3)"
            boundingObject USE L_SHAPE_COXA
            physics Physics {
              density -1
              mass 0.8
            }
          }
        }
      ]
    }
    DEF Leg0MR Pose {
      translation 0.08 0 0
      children [
        DEF JointBC Pose {
          translation -0.008 0 0
          children [
            Shape {
              appearance PBRAppearance {
                baseColor 0.101961 0.101961 0.101961
                roughness 1
                metalness 0.3
              }
              geometry Box {
                size 0.045 0.02 0.045
              }
            }
          ]
        }
        HingeJoint {
          jointParameters HingeJointParameters {
            position -4.9266494739600294e-06
            axis 0 0 -1
          }
          device [
            PositionSensor {
              name "S_MR_COXA"
            }
            RotationalMotor {
              name "M_MR_COXA"
            }
          ]
          endPoint Solid {
            translation 0.01999974874772243 -0.0019998171191071405 1.1721242531390072e-05
            rotation -0.003299999592370501 -0.561680954575035 0.8273473365342804 8.734419577754639e-06
            children [
              DEF JointCF Pose {
                translation 0.022 -1.67293e-08 -1.67294e-08
                rotation 0.5773509358554485 -0.5773509358554485 0.5773489358556708 2.0944
                children [
                  Shape {
                    appearance PBRAppearance {
                      baseColor 0.101961 0.101961 0.101961
                      roughness 1
                      metalness 0.3
                    }
                    geometry Box {
                      size 0.045 0.02 0.045
                    }
                  }
                ]
              }
              DEF R_SHAPE_COXA Shape {
                appearance PBRAppearance {
                  baseColor 0.54902 0.54902 0.54902
                  roughness 1
                  metalness 0.3
                }
                geometry Mesh {
                  url [
                    "../webotsSTL/right-coxa-webots.stl"
                  ]
                }
              }
              HingeJoint {
                jointParameters HingeJointParameters {
                  position 2.3545175193811002e-06
                  axis 0 -1 0
                  anchor 0.0229 0 -0.0077
                }
                device [
                  RotationalMotor {
                    name "M_MR_FEMUR"
                  }
                  PositionSensor {
                    name "S_MR_FEMUR"
                  }
                ]
                endPoint Solid {
                  translation 0.06299998187010378 0 9.441613119196696e-08
                  rotation -0.999999999999232 -9.577499600415854e-07 -7.864797596901286e-07 1.5707953071805552
                  children [
                    HingeJoint {
                      jointParameters HingeJointParameters {
                        position -1.3133558973335656e-06
                        axis 0 0 1
                        anchor 0.041 0.008 0
                      }
                      device [
                        RotationalMotor {
                          name "M_MR_TIBIA"
                        }
                        PositionSensor {
                          name "S_MR_TIBIA"
                        }
                      ]
                      endPoint Solid {
                        translation 0.05602890489376092 0.047957568558271525 2.476705097336627e-05
                        rotation -4.6095190422626895e-07 -0.7071082811859147 0.7071052811838482 3.1415890713191086
                        children [
                          DEF JointFT Pose {
                            translation 0.0118 0 0.035
                            rotation 0.3243588663662829 0.3243588663662829 0.888584633908982 1.68865
                            children [
                              Shape {
                                appearance PBRAppearance {
                                  baseColor 0.101961 0.101961 0.101961
                                  roughness 1
                                  metalness 0.3
                                }
                                geometry Box {
                                  size 0.045 0.02 0.045
                                }
                              }
                            ]
                          }
                          DEF R_SHAPE_TIBIA Shape {
                            appearance PBRAppearance {
                              baseColor 0.513726 0.513726 0.513726
                              roughness 1
                              metalness 0.3
                            }
                            geometry Mesh {
                              url [
                                "../webotsSTL/right-tibia-webots.stl"
                              ]
                            }
                          }
                        ]
                        boundingObject Group {
                          children [
                            Pose {
                              translation -0.033 0 -0.02
                              children [
                                Box {
                                  size 0.01 0.01 0.08
                                }
                              ]
                            }
                          ]
                        }
                        physics Physics {
                          density -1
                          mass 0.8
                        }
                      }
                    }
                    DEF R_SHAPE_FEMUR Shape {
                      appearance PBRAppearance {
                        baseColor 0.505882 0.505882 0.505882
                        roughness 1
                        metalness 0.3
                      }
                      geometry Mesh {
                        url [
                          "../webotsSTL/right-femur-webots.stl"
                        ]
                      }
                    }
                  ]
                  boundingObject USE R_SHAPE_FEMUR
                  physics Physics {
                    density -1
                    mass 0.8
                  }
                }
              }
            ]
            boundingObject USE R_SHAPE_COXA
            physics Physics {
              density -1
              mass 0.8
            }
          }
        }
      ]
    }
    DEF Body Pose {
      children [
        Shape {
          appearance PBRAppearance {
            baseColor 0.533333 0.533333 0.533333
            roughness 1
            metalness 0.3
          }
          geometry Mesh {
            url [
              "../webotsSTL/frame-webots.stl"
            ]
          }
        }
      ]
    }
  ]
  name "Hexapod"
  boundingObject Box {
    size 0.17 0.2 0.02
  }
  physics Physics {
    density 500
  }
  controller "new_hexapod"
}
