#VRML_SIM R2023b utf8

EXTERNPROTO "https://raw.githubusercontent.com/cyberbotics/webots/R2023b/projects/objects/backgrounds/protos/TexturedBackground.proto"
EXTERNPROTO "https://raw.githubusercontent.com/cyberbotics/webots/R2023b/projects/objects/backgrounds/protos/TexturedBackgroundLight.proto"
EXTERNPROTO "https://raw.githubusercontent.com/cyberbotics/webots/R2023b/projects/objects/floors/protos/RectangleArena.proto"
EXTERNPROTO "https://raw.githubusercontent.com/cyberbotics/webots/R2023b/projects/appearances/protos/Parquetry.proto"

WorldInfo {
}
Viewpoint {
  orientation 0.21134694894977443 0.17075106257270822 -0.9623806636668842 2.0802416947815723
  position 0.22521203849454735 0.5153672774286425 0.3920983475327056
  follow "Hexapod"
}
TexturedBackground {
}
RectangleArena {
  floorSize 10 10
  floorAppearance Parquetry {
    type "light strip"
  }
}
TexturedBackgroundLight {
}
Pose {
  translation -0.83 0 0
  children [
    Group {
      children [
        Solid {
          translation -0.019933880692263206 -0.03998729742886506 0.04960760000000001
          rotation 1.6977064384061533e-12 2.625773205149639e-13 -1 5.076325663233382e-05
          children [
            DEF BOX Shape {
              appearance PBRAppearance {
              }
              geometry Box {
                size 0.1 0.1 0.1
              }
            }
          ]
          boundingObject USE BOX
          physics Physics {
          }
          linearVelocity 7.828049301269766e-18 -3.436177098630413e-18 -5.6843418860808e-17
          angularVelocity 5.329070518200732e-16 4.930380657631324e-31 9.946644516877386e-17
        }
        Solid {
          translation 0.06990678014426754 -0.19993550478438063 0.04960760000000001
          rotation -7.10881177941584e-15 2.272364303263095e-13 0.9999999999999999 9.931916513727789e-05
          children [
            DEF BOX Shape {
              appearance PBRAppearance {
              }
              geometry Box {
                size 0.1 0.1 0.1
              }
            }
          ]
          name "solid(1)"
          boundingObject USE BOX
          physics Physics {
          }
          linearVelocity -1.2142985776369125e-17 -4.826442388914132e-18 -5.6843418860808e-17
          angularVelocity 5.32907051820074e-16 -2.664535259100374e-16 -2.3862911275756654e-16
        }
        Solid {
          translation 0.2427788537707931 -0.1300340540610465 0.04960760000000001
          rotation 3.682668554929528e-12 3.800695593871251e-12 -1 2.483653839819131e-05
          children [
            DEF BOX Shape {
              appearance PBRAppearance {
              }
              geometry Box {
                size 0.1 0.1 0.1
              }
            }
          ]
          name "solid(2)"
          boundingObject USE BOX
          physics Physics {
          }
          linearVelocity -2.6787283191166244e-18 3.099478987774192e-17 -5.6843418860808e-17
          angularVelocity -7.993605777301122e-16 2.6645352591003835e-16 5.3328487751619866e-17
        }
        Solid {
          translation 0.24010227170996068 0.2200350097607885 0.0496076
          rotation -7.164314950142934e-13 -8.700438092434452e-13 1 7.175482358364985e-05
          children [
            DEF BOX Shape {
              appearance PBRAppearance {
              }
              geometry Box {
                size 0.1 0.1 0.1
              }
            }
          ]
          name "solid(3)"
          boundingObject USE BOX
          physics Physics {
          }
          linearVelocity -1.278792039593524e-17 5.54670682148809e-17 0
          angularVelocity -1.0658141036401496e-15 -5.329070518200754e-16 2.2802200744783678e-17
        }
        Solid {
          translation -0.020051649108723035 0.15992621635509713 0.0496076
          rotation -2.014393175183035e-13 -2.2760921047098275e-14 -1 0.00017334433090601307
          children [
            DEF BOX Shape {
              appearance PBRAppearance {
              }
              geometry Box {
                size 0.1 0.1 0.1
              }
            }
          ]
          name "solid(4)"
          boundingObject USE BOX
          physics Physics {
          }
          linearVelocity -3.361184906254709e-17 1.199051413134968e-17 0
          angularVelocity -2.664535259100378e-16 -1.0658141036401485e-15 1.3197155190476505e-16
        }
        Solid {
          translation 0.23263016943535741 0.05998653481257025 0.04960760000000001
          rotation 1.5473375884672905e-13 5.835569561192835e-13 -1 2.8865795149727805e-05
          children [
            DEF BOX Shape {
              appearance PBRAppearance {
              }
              geometry Box {
                size 0.1 0.1 0.1
              }
            }
          ]
          name "solid(5)"
          boundingObject USE BOX
          physics Physics {
          }
          linearVelocity 1.6871915144853152e-18 -7.070173381964047e-18 -5.684341886080798e-17
          angularVelocity 5.329070518200748e-16 -1.4791141972893971e-31 -3.752104075037725e-17
        }
      ]
    }
  ]
}
Robot {
  translation 0.0025017257741948816 0.006376704082100901 0.10845369139050172
  rotation 0.002763406179810542 0.27591964380116835 -0.9611767338793223 0.0260536154223626
  children [
    InertialUnit {
      children [
        Shape {
          geometry Cylinder {
            height 0.02
            radius 0.03
          }
        }
      ]
      name "imu"
    }
    DEF Leg0FR Pose {
      translation 0.063 0.082 0
      rotation 0 0 1 0.785398
      children [
        DEF JointBC Pose {
          translation -0.008 0 0
          children [
            Shape {
              appearance PBRAppearance {
                baseColor 0.101961 0.101961 0.101961
                roughness 1
                metalness 0.3
              }
              geometry Box {
                size 0.045 0.02 0.045
              }
            }
          ]
        }
        HingeJoint {
          jointParameters HingeJointParameters {
            position -1.3500074437511334e-07
            axis 0 0 -1
          }
          device [
            PositionSensor {
              name "S_FR_COXA"
            }
            RotationalMotor {
              name "M_FR_COXA"
            }
          ]
          endPoint Solid {
            translation 0.020000000270001303 -0.001999997299985095 0
            rotation 0 0 1 1.3657139822709086e-07
            children [
              DEF JointCF Pose {
                translation 0.022 -1.67293e-08 -1.67294e-08
                rotation 0.5773509358554485 -0.5773509358554485 0.5773489358556708 2.0944
                children [
                  Shape {
                    appearance PBRAppearance {
                      baseColor 0.101961 0.101961 0.101961
                      roughness 1
                      metalness 0.3
                    }
                    geometry Box {
                      size 0.045 0.02 0.045
                    }
                  }
                ]
              }
              DEF R_SHAPE_COXA Shape {
                appearance PBRAppearance {
                  baseColor 0.54902 0.54902 0.54902
                  roughness 1
                  metalness 0.3
                }
                geometry Mesh {
                  url [
                    "../webotsSTL/right-coxa-webots.stl"
                  ]
                }
              }
              HingeJoint {
                jointParameters HingeJointParameters {
                  position 2.8186670669172464e-06
                  axis 0 -1 0
                  anchor 0.0229 0 -0.0077
                }
                device [
                  RotationalMotor {
                    name "M_FR_FEMUR"
                  }
                  PositionSensor {
                    name "S_FR_FEMUR"
                  }
                ]
                endPoint Solid {
                  translation 0.06299997829610413 0 1.1302851881094672e-07
                  rotation -0.9999999999987733 -1.1898249704187665e-06 -1.0185545334862412e-06 1.5707953071810536
                  children [
                    HingeJoint {
                      jointParameters HingeJointParameters {
                        position -3.0652470884851013e-06
                        axis 0 0 1
                        anchor 0.041 0.008 0
                      }
                      device [
                        RotationalMotor {
                          name "M_FR_TIBIA"
                        }
                        PositionSensor {
                          name "S_FR_TIBIA"
                        }
                      ]
                      endPoint Solid {
                        translation 0.05602897489505024 0.0479575422292041 2.476705097336628e-05
                        rotation -1.0803402887247827e-06 -0.7071082811861599 0.7071052811829279 3.1415878325475957
                        children [
                          DEF JointFT Pose {
                            translation 0.0118 0 0.035
                            rotation 0.3243588663662829 0.3243588663662829 0.888584633908982 1.68865
                            children [
                              Shape {
                                appearance PBRAppearance {
                                  baseColor 0.101961 0.101961 0.101961
                                  roughness 1
                                  metalness 0.3
                                }
                                geometry Box {
                                  size 0.045 0.02 0.045
                                }
                              }
                            ]
                          }
                          DEF R_SHAPE_TIBIA Shape {
                            appearance PBRAppearance {
                              baseColor 0.513726 0.513726 0.513726
                              roughness 1
                              metalness 0.3
                            }
                            geometry Mesh {
                              url [
                                "../webotsSTL/right-tibia-webots.stl"
                              ]
                            }
                          }
                        ]
                        boundingObject Group {
                          children [
                            Pose {
                              translation -0.033 0 -0.02
                              children [
                                Box {
                                  size 0.01 0.01 0.08
                                }
                              ]
                            }
                          ]
                        }
                        physics Physics {
                          density -1
                          mass 0.8
                        }
                        linearVelocity -3.6376597954443927e-05 -3.533350738432972e-05 -1.4764711828263444e-07
                        angularVelocity -3.877652513928314e-06 6.882518396551924e-07 -2.0448411147813826e-06
                      }
                    }
                    DEF R_SHAPE_FEMUR Shape {
                      appearance PBRAppearance {
                        baseColor 0.505882 0.505882 0.505882
                        roughness 1
                        metalness 0.3
                      }
                      geometry Mesh {
                        url [
                          "../webotsSTL/right-femur-webots.stl"
                        ]
                      }
                    }
                  ]
                  boundingObject USE R_SHAPE_FEMUR
                  physics Physics {
                    density -1
                    mass 0.8
                  }
                  linearVelocity -2.4469938973510353e-05 -2.3078163592984426e-05 6.231212285712218e-08
                  angularVelocity -3.2780294146739557e-06 -1.5841771362149208e-07 -2.184657512453483e-06
                }
              }
            ]
            name "solid(5)"
            boundingObject USE R_SHAPE_COXA
            physics Physics {
              density -1
              mass 0.8
            }
            linearVelocity -1.2533940803010068e-05 -1.120702262895179e-05 1.9169402257546153e-07
            angularVelocity -1.9198603582944185e-06 -3.4148382205504947e-07 -1.5100085060257594e-06
          }
        }
      ]
    }
    DEF Leg0BR Pose {
      translation 0.06 -0.08 0
      rotation 0 0 1 -0.785395307179586
      children [
        DEF JointBC Pose {
          translation -0.008 0 0
          children [
            Shape {
              appearance PBRAppearance {
                baseColor 0.101961 0.101961 0.101961
                roughness 1
                metalness 0.3
              }
              geometry Box {
                size 0.045 0.02 0.045
              }
            }
          ]
        }
        HingeJoint {
          jointParameters HingeJointParameters {
            position -1.9321457907632194e-07
            axis 0 0 -1
          }
          device [
            PositionSensor {
              name "S_BR_COXA"
            }
            RotationalMotor {
              name "M_BR_COXA"
            }
          ]
          endPoint Solid {
            translation 0.020000000386428785 -0.0019999961357083816 0
            rotation 0 0 1 1.931411236050088e-07
            children [
              DEF JointCF Pose {
                translation 0.022 -1.67293e-08 -1.67294e-08
                rotation 0.5773509358554485 -0.5773509358554485 0.5773489358556708 2.0944
                children [
                  Shape {
                    appearance PBRAppearance {
                      baseColor 0.101961 0.101961 0.101961
                      roughness 1
                      metalness 0.3
                    }
                    geometry Box {
                      size 0.045 0.02 0.045
                    }
                  }
                ]
              }
              DEF R_SHAPE_COXA Shape {
                appearance PBRAppearance {
                  baseColor 0.54902 0.54902 0.54902
                  roughness 1
                  metalness 0.3
                }
                geometry Mesh {
                  url [
                    "../webotsSTL/right-coxa-webots.stl"
                  ]
                }
              }
              HingeJoint {
                jointParameters HingeJointParameters {
                  position 2.5655061339224794e-06
                  axis 0 -1 0
                  anchor 0.0229 0 -0.0077
                }
                device [
                  RotationalMotor {
                    name "M_BR_FEMUR"
                  }
                  PositionSensor {
                    name "S_BR_FEMUR"
                  }
                ]
                endPoint Solid {
                  translation 0.0629999802454706 0 1.0287677063534895e-07
                  rotation -0.9999999999990369 -1.0632443748582632e-06 -8.919740669498799e-07 1.5707953071807692
                  children [
                    HingeJoint {
                      jointParameters HingeJointParameters {
                        position -2.900975458006161e-06
                        axis 0 0 1
                        anchor 0.041 0.008 0
                      }
                      device [
                        RotationalMotor {
                          name "M_BR_TIBIA"
                        }
                        PositionSensor {
                          name "S_BR_TIBIA"
                        }
                      ]
                      endPoint Solid {
                        translation 0.05602896833115942 0.04795754469803779 2.476705097336627e-05
                        rotation -1.0222613735798928e-06 -0.7071082811861483 0.707105281183026 3.1415879487049327
                        children [
                          DEF JointFT Pose {
                            translation 0.0118 0 0.035
                            rotation 0.3243588663662829 0.3243588663662829 0.888584633908982 1.68865
                            children [
                              Shape {
                                appearance PBRAppearance {
                                  baseColor 0.101961 0.101961 0.101961
                                  roughness 1
                                  metalness 0.3
                                }
                                geometry Box {
                                  size 0.045 0.02 0.045
                                }
                              }
                            ]
                          }
                          DEF R_SHAPE_TIBIA Shape {
                            appearance PBRAppearance {
                              baseColor 0.513726 0.513726 0.513726
                              roughness 1
                              metalness 0.3
                            }
                            geometry Mesh {
                              url [
                                "../webotsSTL/right-tibia-webots.stl"
                              ]
                            }
                          }
                        ]
                        boundingObject Group {
                          children [
                            Pose {
                              translation -0.033 0 -0.02
                              children [
                                Box {
                                  size 0.01 0.01 0.08
                                }
                              ]
                            }
                          ]
                        }
                        physics Physics {
                          density -1
                          mass 0.8
                        }
                        linearVelocity -3.436688016179801e-05 3.364355652760054e-05 -4.544080471902135e-08
                        angularVelocity 2.997548223225295e-06 4.903516033253148e-07 -1.1770006759057702e-06
                      }
                    }
                    DEF R_SHAPE_FEMUR Shape {
                      appearance PBRAppearance {
                        baseColor 0.505882 0.505882 0.505882
                        roughness 1
                        metalness 0.3
                      }
                      geometry Mesh {
                        url [
                          "../webotsSTL/right-femur-webots.stl"
                        ]
                      }
                    }
                  ]
                  boundingObject USE R_SHAPE_FEMUR
                  physics Physics {
                    density -1
                    mass 0.8
                  }
                  linearVelocity -2.3155770953522394e-05 2.2458994802505574e-05 1.1910267858183943e-07
                  angularVelocity 2.4936241802999244e-06 -3.500193365493415e-07 -9.726833932413375e-07
                }
              }
            ]
            name "solid(4)"
            boundingObject USE R_SHAPE_COXA
            physics Physics {
              density -1
              mass 0.8
            }
            linearVelocity -1.1956368537440198e-05 1.1521974564914218e-05 2.291959952316347e-07
            angularVelocity 1.2208781398084472e-06 -4.4138311749121757e-07 -1.5697714790312136e-06
          }
        }
      ]
    }
    DEF Leg0FL Pose {
      translation -0.063 0.082 0
      rotation 0 0 1 2.3562
      children [
        DEF JointBC Pose {
          translation -0.008 0 0
          children [
            Shape {
              appearance PBRAppearance {
                baseColor 0.101961 0.101961 0.101961
                roughness 1
                metalness 0.3
              }
              geometry Box {
                size 0.045 0.02 0.045
              }
            }
          ]
        }
        HingeJoint {
          jointParameters HingeJointParameters {
            position -3.3647851220191133e-06
            axis 0 0 -1
          }
          device [
            PositionSensor {
              name "S_FL_COXA"
            }
            RotationalMotor {
              name "M_FL_COXA"
            }
          ]
          endPoint Solid {
            translation 0.01999999343638197 0.002000065635092692 0
            rotation 0 0 1 3.364760068105922e-06
            children [
              DEF JointCF Pose {
                translation 0.022 -1.67293e-08 -1.67294e-08
                rotation 0.5773509358554485 -0.5773509358554485 0.5773489358556708 2.0944
                children [
                  Shape {
                    appearance PBRAppearance {
                      baseColor 0.101961 0.101961 0.101961
                      roughness 1
                      metalness 0.3
                    }
                    geometry Box {
                      size 0.045 0.02 0.045
                    }
                  }
                ]
              }
              DEF L_SHAPE_COXA Shape {
                appearance PBRAppearance {
                  baseColor 0.54902 0.54902 0.54902
                  roughness 1
                  metalness 0.3
                }
                geometry Mesh {
                  url [
                    "../webotsSTL/left-coxa-webots.stl"
                  ]
                }
              }
              HingeJoint {
                jointParameters HingeJointParameters {
                  position -2.7277066270148254e-06
                  axis 0 1 0
                  anchor 0.0229 0 -0.0077
                }
                device [
                  RotationalMotor {
                    name "M_FL_FEMUR"
                  }
                  PositionSensor {
                    name "S_FL_FEMUR"
                  }
                ]
                endPoint Solid {
                  translation 0.06299997899650955 0 1.0938100711722215e-07
                  rotation 0.9999999999981399 -1.3638483039197297e-06 1.3638533135057214e-06 1.570800000001858
                  children [
                    HingeJoint {
                      jointParameters HingeJointParameters {
                        position 2.394180750764363e-06
                        axis 0 0 1
                        anchor 0.04 -0.0095 0
                      }
                      device [
                        RotationalMotor {
                          name "M_FL_TIBIA"
                        }
                        PositionSensor {
                          name "S_FL_TIBIA"
                        }
                      ]
                      endPoint Solid {
                        translation 0.061000099358440966 -0.05099994972208522 -8.485299999999978e-07
                        rotation -8.498606249035423e-07 0.7071062811851203 0.7071072811871105 3.141591692942641
                        children [
                          DEF JointFT Pose {
                            translation 0.012 0 0.0354013
                            rotation 0.3243588663662829 0.3243588663662829 0.888584633908982 1.68865
                            children [
                              Shape {
                                appearance PBRAppearance {
                                  baseColor 0.101961 0.101961 0.101961
                                  roughness 1
                                  metalness 0.3
                                }
                                geometry Box {
                                  size 0.045 0.02 0.045
                                }
                              }
                            ]
                          }
                          DEF L_SHAPE_TIBIA Shape {
                            appearance PBRAppearance {
                              baseColor 0.513726 0.513726 0.513726
                              roughness 1
                              metalness 0.3
                            }
                            geometry Mesh {
                              url [
                                "../webotsSTL/left-tibia-webots.stl"
                              ]
                            }
                          }
                        ]
                        boundingObject Group {
                          children [
                            Pose {
                              translation -0.033 0 -0.02
                              children [
                                Box {
                                  size 0.01 0.01 0.08
                                }
                              ]
                            }
                          ]
                        }
                        physics Physics {
                          density -1
                          mass 0.8
                        }
                        linearVelocity 4.8910283965109555e-05 1.5874073905869577e-05 -5.5730311349451476e-08
                        angularVelocity 2.404209798536232e-06 -6.829047289892366e-06 -6.487029483655423e-06
                      }
                    }
                    DEF L_SHAPE_FEMUR Shape {
                      appearance PBRAppearance {
                        baseColor 0.505882 0.505882 0.505882
                        roughness 1
                        metalness 0.3
                      }
                      geometry Mesh {
                        url [
                          "../webotsSTL/left-femur-webots.stl"
                        ]
                      }
                    }
                  ]
                  boundingObject USE L_SHAPE_FEMUR
                  physics Physics {
                    density -1
                    mass 0.8
                  }
                  linearVelocity 3.175647861325934e-05 1.065659591803464e-05 -1.3692828088960424e-07
                  angularVelocity 2.313667842140346e-06 -5.939774737071729e-06 -3.592414832867762e-06
                }
              }
            ]
            name "solid(2)"
            boundingObject USE L_SHAPE_COXA
            physics Physics {
              density -1
              mass 0.8
            }
            linearVelocity 1.550329329617739e-05 5.791124031162553e-06 -3.921199418499555e-08
            angularVelocity 4.7472960803837506e-07 -3.392621207920625e-06 -3.091225890607953e-06
          }
        }
      ]
    }
    DEF Leg0BL Pose {
      translation -0.06 -0.08 0
      rotation 0 0 -1 2.35619
      children [
        DEF JointBC Pose {
          translation -0.008 0 0
          children [
            Shape {
              appearance PBRAppearance {
                baseColor 0.101961 0.101961 0.101961
                roughness 1
                metalness 0.3
              }
              geometry Box {
                size 0.045 0.02 0.045
              }
            }
          ]
        }
        HingeJoint {
          jointParameters HingeJointParameters {
            position 4.194089921735755e-06
            axis 0 0 -1
          }
          device [
            PositionSensor {
              name "S_BL_COXA"
            }
            RotationalMotor {
              name "M_BL_COXA"
            }
          ]
          endPoint Solid {
            translation 0.02000000855405681 0.0019999144575842927 0
            rotation 0 0 -1 4.194087934481993e-06
            children [
              DEF JointCF Pose {
                translation 0.022 -1.67293e-08 -1.67294e-08
                rotation 0.5773509358554485 -0.5773509358554485 0.5773489358556708 2.0944
                children [
                  Shape {
                    appearance PBRAppearance {
                      baseColor 0.101961 0.101961 0.101961
                      roughness 1
                      metalness 0.3
                    }
                    geometry Box {
                      size 0.045 0.02 0.045
                    }
                  }
                ]
              }
              DEF L_SHAPE_COXA Shape {
                appearance PBRAppearance {
                  baseColor 0.54902 0.54902 0.54902
                  roughness 1
                  metalness 0.3
                }
                geometry Mesh {
                  url [
                    "../webotsSTL/left-coxa-webots.stl"
                  ]
                }
              }
              HingeJoint {
                jointParameters HingeJointParameters {
                  position -2.568001274183551e-06
                  axis 0 1 0
                  anchor 0.0229 0 -0.0077
                }
                device [
                  RotationalMotor {
                    name "M_BL_FEMUR"
                  }
                  PositionSensor {
                    name "S_BL_FEMUR"
                  }
                ]
                endPoint Solid {
                  translation 0.06299998022625773 0 1.0297682572109335e-07
                  rotation 0.9999999999983513 -1.2839959208583444e-06 1.2840006370903642e-06 1.570800000001647
                  children [
                    HingeJoint {
                      jointParameters HingeJointParameters {
                        position 2.1777828103086705e-06
                        axis 0 0 1
                        anchor 0.04 -0.0095 0
                      }
                      device [
                        RotationalMotor {
                          name "M_BL_TIBIA"
                        }
                        PositionSensor {
                          name "S_BL_TIBIA"
                        }
                      ]
                      endPoint Solid {
                        translation 0.06100009037793679 -0.05099995426646247 -8.485299999999973e-07
                        rotation -7.733524534932071e-07 0.7071062811852361 0.7071072811870824 3.141591539926082
                        children [
                          DEF JointFT Pose {
                            translation 0.012 0 0.0354013
                            rotation 0.3243588663662829 0.3243588663662829 0.888584633908982 1.68865
                            children [
                              Shape {
                                appearance PBRAppearance {
                                  baseColor 0.101961 0.101961 0.101961
                                  roughness 1
                                  metalness 0.3
                                }
                                geometry Box {
                                  size 0.045 0.02 0.045
                                }
                              }
                            ]
                          }
                          DEF L_SHAPE_TIBIA Shape {
                            appearance PBRAppearance {
                              baseColor 0.513726 0.513726 0.513726
                              roughness 1
                              metalness 0.3
                            }
                            geometry Mesh {
                              url [
                                "../webotsSTL/left-tibia-webots.stl"
                              ]
                            }
                          }
                        ]
                        boundingObject Group {
                          children [
                            Pose {
                              translation -0.033 0 -0.02
                              children [
                                Box {
                                  size 0.01 0.01 0.08
                                }
                              ]
                            }
                          ]
                        }
                        physics Physics {
                          density -1
                          mass 0.8
                        }
                        linearVelocity 5.0235688161372825e-05 -2.9407966299306184e-05 8.366481360386401e-08
                        angularVelocity -4.544974949592404e-06 -7.23482840500179e-06 4.402591603333072e-06
                      }
                    }
                    DEF L_SHAPE_FEMUR Shape {
                      appearance PBRAppearance {
                        baseColor 0.505882 0.505882 0.505882
                        roughness 1
                        metalness 0.3
                      }
                      geometry Mesh {
                        url [
                          "../webotsSTL/left-femur-webots.stl"
                        ]
                      }
                    }
                  ]
                  boundingObject USE L_SHAPE_FEMUR
                  physics Physics {
                    density -1
                    mass 0.8
                  }
                  linearVelocity 3.2597171255877704e-05 -1.909679122107505e-05 -5.751967771705505e-08
                  angularVelocity -3.455373659455871e-06 -5.650047702338453e-06 1.4822868266979285e-06
                }
              }
            ]
            name "solid(1)"
            boundingObject USE L_SHAPE_COXA
            physics Physics {
              density -1
              mass 0.8
            }
            linearVelocity 1.583546757316867e-05 -9.266226863857697e-06 4.181429034133544e-09
            angularVelocity -1.5406551955329058e-06 -3.452358049059704e-06 5.902886172789495e-07
          }
        }
      ]
    }
    DEF Leg0ML Pose {
      translation -0.08 0 0
      rotation 0 0 -1 3.14159
      children [
        DEF JointBC Pose {
          translation -0.008 0 0
          children [
            Shape {
              appearance PBRAppearance {
                baseColor 0.101961 0.101961 0.101961
                roughness 1
                metalness 0.3
              }
              geometry Box {
                size 0.045 0.02 0.045
              }
            }
          ]
        }
        HingeJoint {
          jointParameters HingeJointParameters {
            position -5.628494616453136e-06
            axis 0 0 -1
          }
          device [
            PositionSensor {
              name "S_ML_COXA"
            }
            RotationalMotor {
              name "M_ML_COXA"
            }
          ]
          endPoint Solid {
            translation 0.01999998890876315 0.0020001109092625978 0
            rotation 0 0 1 5.6284587476399765e-06
            children [
              DEF JointCF Pose {
                translation 0.022 -1.67293e-08 -1.67294e-08
                rotation 0.5773509358554485 -0.5773509358554485 0.5773489358556708 2.0944
                children [
                  Shape {
                    appearance PBRAppearance {
                      baseColor 0.101961 0.101961 0.101961
                      roughness 1
                      metalness 0.3
                    }
                    geometry Box {
                      size 0.045 0.02 0.045
                    }
                  }
                ]
              }
              DEF L_SHAPE_COXA Shape {
                appearance PBRAppearance {
                  baseColor 0.54902 0.54902 0.54902
                  roughness 1
                  metalness 0.3
                }
                geometry Mesh {
                  url [
                    "../webotsSTL/left-coxa-webots.stl"
                  ]
                }
              }
              HingeJoint {
                jointParameters HingeJointParameters {
                  position -1.3513184624613928e-06
                  axis 0 1 0
                  anchor 0.0229 0 -0.0077
                }
                device [
                  RotationalMotor {
                    name "M_ML_FEMUR"
                  }
                  PositionSensor {
                    name "S_ML_FEMUR"
                  }
                ]
                endPoint Solid {
                  translation 0.06299998959481096 0 5.418786332579001e-08
                  rotation 0.9999999999995437 -6.756567495178708e-07 6.756592312304909e-07 1.5708000000004545
                  children [
                    HingeJoint {
                      jointParameters HingeJointParameters {
                        position 2.298967434422039e-06
                        axis 0 0 1
                        anchor 0.04 -0.0095 0
                      }
                      device [
                        RotationalMotor {
                          name "M_ML_TIBIA"
                        }
                        PositionSensor {
                          name "S_ML_TIBIA"
                        }
                      ]
                      endPoint Solid {
                        translation 0.061000095407093016 -0.05099995172157409 -8.485299999999969e-07
                        rotation -8.161976579400046e-07 0.7071062811851719 0.7071072811870985 3.141591625616612
                        children [
                          DEF JointFT Pose {
                            translation 0.012 0 0.0354013
                            rotation 0.3243588663662829 0.3243588663662829 0.888584633908982 1.68865
                            children [
                              Shape {
                                appearance PBRAppearance {
                                  baseColor 0.101961 0.101961 0.101961
                                  roughness 1
                                  metalness 0.3
                                }
                                geometry Box {
                                  size 0.045 0.02 0.045
                                }
                              }
                            ]
                          }
                          DEF L_SHAPE_TIBIA Shape {
                            appearance PBRAppearance {
                              baseColor 0.513726 0.513726 0.513726
                              roughness 1
                              metalness 0.3
                            }
                            geometry Mesh {
                              url [
                                "../webotsSTL/left-tibia-webots.stl"
                              ]
                            }
                          }
                        ]
                        boundingObject Group {
                          children [
                            Pose {
                              translation -0.033 0 -0.02
                              children [
                                Box {
                                  size 0.01 0.01 0.08
                                }
                              ]
                            }
                          ]
                        }
                        physics Physics {
                          density -1
                          mass 0.8
                        }
                        linearVelocity 2.5679558147597703e-05 9.750414240108362e-06 -2.2428218048986537e-07
                        angularVelocity 1.0516795065228531e-06 -3.6439272270204594e-06 1.541848656702046e-05
                      }
                    }
                    DEF L_SHAPE_FEMUR Shape {
                      appearance PBRAppearance {
                        baseColor 0.505882 0.505882 0.505882
                        roughness 1
                        metalness 0.3
                      }
                      geometry Mesh {
                        url [
                          "../webotsSTL/left-femur-webots.stl"
                        ]
                      }
                    }
                  ]
                  boundingObject USE L_SHAPE_FEMUR
                  physics Physics {
                    density -1
                    mass 0.8
                  }
                  linearVelocity 1.6557800731078486e-05 7.217293463384067e-06 -2.1849892792857872e-07
                  angularVelocity 8.153959171275462e-07 -3.0501230105045988e-06 1.569394451598309e-05
                }
              }
            ]
            name "solid(3)"
            boundingObject USE L_SHAPE_COXA
            physics Physics {
              density -1
              mass 0.8
            }
            linearVelocity 7.857533336306233e-06 4.3070357937935455e-06 -6.516916943866135e-08
            angularVelocity 2.663745421460007e-07 -2.5566202682035162e-06 1.6219274069544452e-05
          }
        }
      ]
    }
    DEF Leg0MR Pose {
      translation 0.08 0 0
      children [
        DEF JointBC Pose {
          translation -0.008 0 0
          children [
            Shape {
              appearance PBRAppearance {
                baseColor 0.101961 0.101961 0.101961
                roughness 1
                metalness 0.3
              }
              geometry Box {
                size 0.045 0.02 0.045
              }
            }
          ]
        }
        HingeJoint {
          jointParameters HingeJointParameters {
            position -1.401466590484743e-07
            axis 0 0 -1
          }
          device [
            PositionSensor {
              name "S_MR_COXA"
            }
            RotationalMotor {
              name "M_MR_COXA"
            }
          ]
          endPoint Solid {
            translation 0.01999973917536309 -0.0019999128479379147 1.1721242531390108e-05
            rotation -0.005262637127659923 -0.8953696284389775 0.44529263762104804 5.478766090298453e-06
            children [
              DEF JointCF Pose {
                translation 0.022 -1.67293e-08 -1.67294e-08
                rotation 0.5773509358554485 -0.5773509358554485 0.5773489358556708 2.0944
                children [
                  Shape {
                    appearance PBRAppearance {
                      baseColor 0.101961 0.101961 0.101961
                      roughness 1
                      metalness 0.3
                    }
                    geometry Box {
                      size 0.045 0.02 0.045
                    }
                  }
                ]
              }
              DEF R_SHAPE_COXA Shape {
                appearance PBRAppearance {
                  baseColor 0.54902 0.54902 0.54902
                  roughness 1
                  metalness 0.3
                }
                geometry Mesh {
                  url [
                    "../webotsSTL/right-coxa-webots.stl"
                  ]
                }
              }
              HingeJoint {
                jointParameters HingeJointParameters {
                  position 4.240983688730271e-06
                  axis 0 -1 0
                  anchor 0.0229 0 -0.0077
                }
                device [
                  RotationalMotor {
                    name "M_MR_FEMUR"
                  }
                  PositionSensor {
                    name "S_MR_FEMUR"
                  }
                ]
                endPoint Solid {
                  translation 0.0629999673440648 0 1.7006337667789528e-07
                  rotation -0.9999999999966971 -1.9009840064104312e-06 -1.7297128443307839e-06 1.5707953071832514
                  children [
                    HingeJoint {
                      jointParameters HingeJointParameters {
                        position -4.072876156752114e-06
                        axis 0 0 1
                        anchor 0.041 0.008 0
                      }
                      device [
                        RotationalMotor {
                          name "M_MR_TIBIA"
                        }
                        PositionSensor {
                          name "S_MR_TIBIA"
                        }
                      ]
                      endPoint Solid {
                        translation 0.05602901515742365 0.04795752708555187 2.476705097336628e-05
                        rotation -1.4365917179798272e-06 -0.7071082811861779 0.707105281182276 3.1415871200477596
                        children [
                          DEF JointFT Pose {
                            translation 0.0118 0 0.035
                            rotation 0.3243588663662829 0.3243588663662829 0.888584633908982 1.68865
                            children [
                              Shape {
                                appearance PBRAppearance {
                                  baseColor 0.101961 0.101961 0.101961
                                  roughness 1
                                  metalness 0.3
                                }
                                geometry Box {
                                  size 0.045 0.02 0.045
                                }
                              }
                            ]
                          }
                          DEF R_SHAPE_TIBIA Shape {
                            appearance PBRAppearance {
                              baseColor 0.513726 0.513726 0.513726
                              roughness 1
                              metalness 0.3
                            }
                            geometry Mesh {
                              url [
                                "../webotsSTL/right-tibia-webots.stl"
                              ]
                            }
                          }
                        ]
                        boundingObject Group {
                          children [
                            Pose {
                              translation -0.033 0 -0.02
                              children [
                                Box {
                                  size 0.01 0.01 0.08
                                }
                              ]
                            }
                          ]
                        }
                        physics Physics {
                          density -1
                          mass 0.8
                        }
                        linearVelocity -5.463003120684817e-05 5.5380782619662835e-06 9.9274730871457e-08
                        angularVelocity 3.4499906806187283e-07 2.5571561606656375e-06 -5.074360430815444e-06
                      }
                    }
                    DEF R_SHAPE_FEMUR Shape {
                      appearance PBRAppearance {
                        baseColor 0.505882 0.505882 0.505882
                        roughness 1
                        metalness 0.3
                      }
                      geometry Mesh {
                        url [
                          "../webotsSTL/right-femur-webots.stl"
                        ]
                      }
                    }
                  ]
                  boundingObject USE R_SHAPE_FEMUR
                  physics Physics {
                    density -1
                    mass 0.8
                  }
                  linearVelocity -3.648707753455938e-05 4.002880484268445e-06 1.9407600639453905e-07
                  angularVelocity 1.3820909315731123e-07 1.4525741603041225e-06 -5.153140706278318e-06
                }
              }
            ]
            boundingObject USE R_SHAPE_COXA
            physics Physics {
              density -1
              mass 0.8
            }
            linearVelocity -1.858737104299735e-05 2.376998367576988e-06 2.5892176406472347e-07
            angularVelocity -1.1051766964866696e-07 3.251066482326428e-07 -5.361111429505909e-06
          }
        }
      ]
    }
    DEF Body Pose {
      children [
        Shape {
          appearance PBRAppearance {
            baseColor 0.533333 0.533333 0.533333
            roughness 1
            metalness 0.3
          }
          geometry Mesh {
            url [
              "../webotsSTL/frame-webots.stl"
            ]
          }
        }
      ]
    }
  ]
  name "Hexapod"
  boundingObject Box {
    size 0.17 0.2 0.02
  }
  physics Physics {
    density 500
  }
  controller "new_hexapod"
  linearVelocity -6.575037526304454e-07 6.747213239363833e-07 1.2904977767187333e-07
  angularVelocity -2.939695706495958e-07 -1.6262042372789692e-06 -1.4846049515159352e-06
}
