#VRML_SIM R2023b utf8

EXTERNPROTO "https://raw.githubusercontent.com/cyberbotics/webots/R2023b/projects/objects/backgrounds/protos/TexturedBackground.proto"
EXTERNPROTO "https://raw.githubusercontent.com/cyberbotics/webots/R2023b/projects/objects/backgrounds/protos/TexturedBackgroundLight.proto"
EXTERNPROTO "https://raw.githubusercontent.com/cyberbotics/webots/R2023b/projects/objects/floors/protos/RectangleArena.proto"
EXTERNPROTO "https://raw.githubusercontent.com/cyberbotics/webots/R2023b/projects/appearances/protos/Parquetry.proto"

WorldInfo {
}
Viewpoint {
  orientation 0.3965763746362868 -0.338102590111392 -0.8534716267341917 4.556922777048294
  position 0.2501688703794389 -2.107656877012379 2.537064094010028
  follow "Hexapod"
}
TexturedBackground {
}
RectangleArena {
  translation 0 -0.02 0
  floorSize 10 10
  floorAppearance Parquetry {
    type "light strip"
  }
}
TexturedBackgroundLight {
}
Pose {
  translation -0.83 0 0
  children [
    Group {
      children [
        Solid {
          translation -0.019933880692263206 -0.039987297428865046 0.049607600000046145
          rotation 5.21925777001904e-13 9.344123967912412e-13 -1 5.076325663243221e-05
          children [
            DEF BOX Shape {
              appearance PBRAppearance {
              }
              geometry Box {
                size 0.1 0.1 0.1
              }
            }
          ]
          boundingObject USE BOX
          physics Physics {
          }
          linearVelocity 5.435870652918421e-17 8.921050547609862e-18 -3.6141045711703117e-13
          angularVelocity 4.930380657631324e-31 1.332267629550187e-15 -8.001753391310315e-17
        }
        Solid {
          translation 0.06990678014426754 -0.19993550478438063 0.04960760000004615
          rotation 2.503931595405959e-13 -7.171222056241628e-13 1 9.931916513680353e-05
          children [
            DEF BOX Shape {
              appearance PBRAppearance {
              }
              geometry Box {
                size 0.1 0.1 0.1
              }
            }
          ]
          name "solid(1)"
          boundingObject USE BOX
          physics Physics {
          }
          linearVelocity 4.603572648516445e-17 -1.037633356837552e-17 -3.613536136981477e-13
          angularVelocity 2.664535259100374e-16 1.06581410364015e-15 1.277317458056406e-16
        }
        Solid {
          translation 0.30173801120117993 -0.1900167535377724 0.04960760000004616
          rotation -7.160010726185213e-13 1.8114827698369645e-13 1 0.0001924591434797972
          children [
            DEF BOX Shape {
              appearance PBRAppearance {
              }
              geometry Box {
                size 0.1 0.1 0.1
              }
            }
          ]
          name "solid(2)"
          boundingObject USE BOX
          physics Physics {
          }
          linearVelocity 2.4786335982247246e-17 -2.306056355630887e-18 -3.6135361369815687e-13
          angularVelocity -5.329070518200752e-16 0 -2.52860180014887e-16
        }
        Solid {
          translation 0.5209886151152492 0.22358406143356147 0.06440520000000013
          rotation -2.417425672521453e-14 -1.0354388756110536e-14 -1 0.0005650171340589228
          children [
            DEF BOX Shape {
              appearance PBRAppearance {
              }
              geometry Box {
                size 0.3 0.6 0.15
              }
            }
          ]
          name "solid(3)"
          boundingObject USE BOX
          physics Physics {
          }
          linearVelocity -2.5598008350995227e-18 -2.174514227229312e-18 -1.2800295802730529e-15
          angularVelocity -4.031212114845533e-32 -3.4512664603419266e-31 2.9616242736568994e-17
        }
        Solid {
          translation -0.020051649108723035 0.15992621635509713 0.049607600000046145
          rotation 9.369900400562668e-14 -1.2111193984567733e-13 -0.9999999999999999 0.0001733443309059252
          children [
            DEF BOX Shape {
              appearance PBRAppearance {
              }
              geometry Box {
                size 0.1 0.1 0.1
              }
            }
          ]
          name "solid(4)"
          boundingObject USE BOX
          physics Physics {
          }
          linearVelocity -6.563555421368687e-17 -1.0649479863927927e-18 -3.6141045711702703e-13
          angularVelocity -5.329070518200752e-16 -1.332267629550187e-15 -5.337140952149074e-18
        }
        Solid {
          translation 0.1890043893105372 0.021583017823547407 0.04960760000004616
          rotation 2.1192975106447155e-15 1.3507743539247444e-15 -1 0.020179439358772883
          children [
            DEF BOX Shape {
              appearance PBRAppearance {
              }
              geometry Box {
                size 0.1 0.1 0.1
              }
            }
          ]
          name "solid(5)"
          boundingObject USE BOX
          physics Physics {
          }
          linearVelocity -6.246734395254693e-17 1.7244759663590344e-17 -3.6135361369817595e-13
          angularVelocity -2.66453525910037e-16 -1.332267629550187e-15 -2.0983497418468634e-16
        }
      ]
    }
  ]
}
Robot {
  translation -0.12462689501521629 0.2223344607003329 0.31916826055938247
  rotation -0.0009160377249977624 -0.03627940661808904 -0.9993412657997895 0.09512881009176694
  children [
    InertialUnit {
      children [
        Shape {
          geometry Cylinder {
            height 0.02
            radius 0.03
          }
        }
      ]
      name "imu"
    }
    DEF Leg0FR Pose {
      translation 0.063 0.082 0
      rotation 0 0 1 0.785398
      children [
        DEF JointBC Pose {
          translation -0.008 0 0
          children [
            Shape {
              appearance PBRAppearance {
                baseColor 0.101961 0.101961 0.101961
                roughness 1
                metalness 0.3
              }
              geometry Box {
                size 0.045 0.02 0.045
              }
            }
          ]
        }
        HingeJoint {
          jointParameters HingeJointParameters {
            position -1.056703063119507e-06
            axis 0 0 -1
          }
          device [
            PositionSensor {
              name "S_FR_COXA"
            }
            RotationalMotor {
              name "M_FR_COXA"
            }
          ]
          endPoint Solid {
            translation 0.020000002113394925 -0.001999978865937615 0
            rotation 0 0 0.9999999999999999 1.056617373301747e-06
            children [
              DEF JointCF Pose {
                translation 0.022 -1.67293e-08 -1.67294e-08
                rotation 0.5773509358554485 -0.5773509358554485 0.5773489358556708 2.0944
                children [
                  Shape {
                    appearance PBRAppearance {
                      baseColor 0.101961 0.101961 0.101961
                      roughness 1
                      metalness 0.3
                    }
                    geometry Box {
                      size 0.045 0.02 0.045
                    }
                  }
                ]
              }
              DEF R_SHAPE_COXA Shape {
                appearance PBRAppearance {
                  baseColor 0.54902 0.54902 0.54902
                  roughness 1
                  metalness 0.3
                }
                geometry Mesh {
                  url [
                    "../webotsSTL/right-coxa-webots.stl"
                  ]
                }
              }
              HingeJoint {
                jointParameters HingeJointParameters {
                  position -1.12137498207017e-07
                  axis 0 -1 0
                  anchor 0.0229 0 -0.0077
                }
                device [
                  RotationalMotor {
                    name "M_FR_FEMUR"
                  }
                  PositionSensor {
                    name "S_FR_FEMUR"
                  }
                ]
                endPoint Solid {
                  translation 0.06300000086345765 0 -4.49671381814315e-09
                  rotation -0.9999999999998621 2.7557880589699655e-07 4.468477491534688e-07 1.5707953071797014
                  children [
                    HingeJoint {
                      jointParameters HingeJointParameters {
                        position -6.84271186896401e-07
                        axis 0 0 1
                        anchor 0.041 0.008 0
                      }
                      device [
                        RotationalMotor {
                          name "M_FR_TIBIA"
                        }
                        PositionSensor {
                          name "S_FR_TIBIA"
                        }
                      ]
                      endPoint Solid {
                        translation 0.056028879757062486 0.04795757801271783 2.4767050973366074e-05
                        rotation -2.385364001541276e-07 -0.7071082811857607 0.707105281184112 3.1415895161482297
                        children [
                          TouchSensor {
                            translation -0.03 -0.0015 -0.06
                            name "FR"
                            boundingObject Group {
                              children [
                                Pose {
                                  translation -0.003 -0.0015 0.04
                                  children [
                                    Box {
                                      size 0.01 0.01 0.08
                                    }
                                  ]
                                }
                              ]
                            }
                          }
                          DEF JointFT Pose {
                            translation 0.0118 0 0.035
                            rotation 0.3243588663662829 0.3243588663662829 0.888584633908982 1.68865
                            children [
                              Shape {
                                appearance PBRAppearance {
                                  baseColor 0.101961 0.101961 0.101961
                                  roughness 1
                                  metalness 0.3
                                }
                                geometry Box {
                                  size 0.045 0.02 0.045
                                }
                              }
                            ]
                          }
                          DEF R_SHAPE_TIBIA Shape {
                            appearance PBRAppearance {
                              baseColor 0.513726 0.513726 0.513726
                              roughness 1
                              metalness 0.3
                            }
                            geometry Mesh {
                              url [
                                "../webotsSTL/right-tibia-webots.stl"
                              ]
                            }
                          }
                        ]
                        boundingObject Group {
                          children [
                            Pose {
                              translation -0.033 -0.0015 -0.02
                              children [
                                Box {
                                  size 0.01 0.01 0.08
                                }
                              ]
                            }
                          ]
                        }
                        physics Physics {
                          density -1
                          mass 0.8
                        }
                        linearVelocity -0.08368852176831558 0.00733812817672107 -0.001585470128212485
                        angularVelocity -0.028052740020910898 -0.33169211301655643 -0.0004788274692664496
                      }
                    }
                    DEF R_SHAPE_FEMUR Shape {
                      appearance PBRAppearance {
                        baseColor 0.505882 0.505882 0.505882
                        roughness 1
                        metalness 0.3
                      }
                      geometry Mesh {
                        url [
                          "../webotsSTL/right-femur-webots.stl"
                        ]
                      }
                    }
                  ]
                  boundingObject USE R_SHAPE_FEMUR
                  physics Physics {
                    density -1
                    mass 0.8
                  }
                  linearVelocity -0.10738995425116217 0.009371337278126269 -0.02138971460044079
                  angularVelocity -0.028046210706485674 -0.3316984507647803 -0.00047812814175487474
                }
              }
            ]
            name "solid(5)"
            boundingObject USE R_SHAPE_COXA
            physics Physics {
              density -1
              mass 0.8
            }
            linearVelocity -0.10664831243457784 0.009330737936631358 -0.03661083005597604
            angularVelocity -0.028029385068656393 -0.33171775136678955 -0.0004754885182109581
          }
        }
      ]
    }
    DEF Leg0BR Pose {
      translation 0.06 -0.08 0
      rotation 0 0 1 -0.785395307179586
      children [
        DEF JointBC Pose {
          translation -0.008 0 0
          children [
            Shape {
              appearance PBRAppearance {
                baseColor 0.101961 0.101961 0.101961
                roughness 1
                metalness 0.3
              }
              geometry Box {
                size 0.045 0.02 0.045
              }
            }
          ]
        }
        HingeJoint {
          jointParameters HingeJointParameters {
            position -2.0027554914732014e-06
            axis 0 0 -1
          }
          device [
            PositionSensor {
              name "S_BR_COXA"
            }
            RotationalMotor {
              name "M_BR_COXA"
            }
          ]
          endPoint Solid {
            translation 0.02000000400547088 -0.0019999599448861597 0
            rotation 0 0 1 2.0027515430941754e-06
            children [
              DEF JointCF Pose {
                translation 0.022 -1.67293e-08 -1.67294e-08
                rotation 0.5773509358554485 -0.5773509358554485 0.5773489358556708 2.0944
                children [
                  Shape {
                    appearance PBRAppearance {
                      baseColor 0.101961 0.101961 0.101961
                      roughness 1
                      metalness 0.3
                    }
                    geometry Box {
                      size 0.045 0.02 0.045
                    }
                  }
                ]
              }
              DEF R_SHAPE_COXA Shape {
                appearance PBRAppearance {
                  baseColor 0.54902 0.54902 0.54902
                  roughness 1
                  metalness 0.3
                }
                geometry Mesh {
                  url [
                    "../webotsSTL/right-coxa-webots.stl"
                  ]
                }
              }
              HingeJoint {
                jointParameters HingeJointParameters {
                  position -2.2266165764521712e-07
                  axis 0 -1 0
                  anchor 0.0229 0 -0.0077
                }
                device [
                  RotationalMotor {
                    name "M_BR_FEMUR"
                  }
                  PositionSensor {
                    name "S_BR_FEMUR"
                  }
                ]
                endPoint Solid {
                  translation 0.06300000171449292 0 -8.928732653408489e-09
                  rotation -0.9999999999998193 3.3084094240376255e-07 5.021098287946589e-07 1.5707953071797378
                  children [
                    HingeJoint {
                      jointParameters HingeJointParameters {
                        position -6.306843114887057e-07
                        axis 0 0 1
                        anchor 0.041 0.008 0
                      }
                      device [
                        RotationalMotor {
                          name "M_BR_TIBIA"
                        }
                        PositionSensor {
                          name "S_BR_TIBIA"
                        }
                      ]
                      endPoint Solid {
                        translation 0.05602856582452046 0.04797003158168924 2.2835050661695868e-05
                        rotation -1.9218997112724465e-07 -0.7071080663892778 0.7071054959814553 3.1415897487243907
                        children [
                          TouchSensor {
                            translation 0 -0.0015 0
                            name "BR"
                            boundingObject Group {
                              children [
                                Pose {
                                  translation -0.033 0 -0.02
                                  children [
                                    Box {
                                      size 0.01 0.01 0.08
                                    }
                                  ]
                                }
                              ]
                            }
                          }
                          DEF JointFT Pose {
                            translation 0.0118 0 0.035
                            rotation 0.3243588663662829 0.3243588663662829 0.888584633908982 1.68865
                            children [
                              Shape {
                                appearance PBRAppearance {
                                  baseColor 0.101961 0.101961 0.101961
                                  roughness 1
                                  metalness 0.3
                                }
                                geometry Box {
                                  size 0.045 0.02 0.045
                                }
                              }
                            ]
                          }
                          DEF R_SHAPE_TIBIA Shape {
                            appearance PBRAppearance {
                              baseColor 0.513726 0.513726 0.513726
                              roughness 1
                              metalness 0.3
                            }
                            geometry Mesh {
                              url [
                                "../webotsSTL/right-tibia-webots.stl"
                              ]
                            }
                          }
                        ]
                        boundingObject Group {
                          children [
                            Pose {
                              translation -0.033 0 -0.02
                              children [
                                Box {
                                  size 0.01 0.01 0.08
                                }
                              ]
                            }
                          ]
                        }
                        physics Physics {
                          density -1
                          mass 0.8
                        }
                        linearVelocity -0.08388801655818208 0.007364801766534197 -0.004617191092117743
                        angularVelocity -0.027973851005830306 -0.33170208036886284 -0.0004722011664524793
                      }
                    }
                    DEF R_SHAPE_FEMUR Shape {
                      appearance PBRAppearance {
                        baseColor 0.505882 0.505882 0.505882
                        roughness 1
                        metalness 0.3
                      }
                      geometry Mesh {
                        url [
                          "../webotsSTL/right-femur-webots.stl"
                        ]
                      }
                    }
                  ]
                  boundingObject USE R_SHAPE_FEMUR
                  physics Physics {
                    density -1
                    mass 0.8
                  }
                  linearVelocity -0.10754054490110677 0.009388660633369341 -0.02489447341164105
                  angularVelocity -0.027980754816876226 -0.33170662454708316 -0.00047289355293451095
                }
              }
            ]
            name "solid(4)"
            boundingObject USE R_SHAPE_COXA
            physics Physics {
              density -1
              mass 0.8
            }
            linearVelocity -0.10674611389141805 0.009341296041062012 -0.03830066176002582
            angularVelocity -0.02799957349004437 -0.33172120559364093 -0.00047560736543826414
          }
        }
      ]
    }
    DEF Leg0FL Pose {
      translation -0.063 0.082 0
      rotation 0 0 1 2.3562
      children [
        DEF JointBC Pose {
          translation -0.008 0 0
          children [
            Shape {
              appearance PBRAppearance {
                baseColor 0.101961 0.101961 0.101961
                roughness 1
                metalness 0.3
              }
              geometry Box {
                size 0.045 0.02 0.045
              }
            }
          ]
        }
        HingeJoint {
          jointParameters HingeJointParameters {
            position 2.5928986459937647e-06
            axis 0 0 -1
          }
          device [
            PositionSensor {
              name "S_FL_COXA"
            }
            RotationalMotor {
              name "M_FL_COXA"
            }
          ]
          endPoint Solid {
            translation 0.020000005351785678 0.0019999464814209446 0
            rotation 0 0 -1 2.5929733197877083e-06
            children [
              DEF JointCF Pose {
                translation 0.022 -1.67293e-08 -1.67294e-08
                rotation 0.5773509358554485 -0.5773509358554485 0.5773489358556708 2.0944
                children [
                  Shape {
                    appearance PBRAppearance {
                      baseColor 0.101961 0.101961 0.101961
                      roughness 1
                      metalness 0.3
                    }
                    geometry Box {
                      size 0.045 0.02 0.045
                    }
                  }
                ]
              }
              DEF L_SHAPE_COXA Shape {
                appearance PBRAppearance {
                  baseColor 0.54902 0.54902 0.54902
                  roughness 1
                  metalness 0.3
                }
                geometry Mesh {
                  url [
                    "../webotsSTL/left-coxa-webots.stl"
                  ]
                }
              }
              HingeJoint {
                jointParameters HingeJointParameters {
                  position 6.258780606350439e-07
                  axis 0 1 0
                  anchor 0.0229 0 -0.0077
                }
                device [
                  RotationalMotor {
                    name "M_FL_FEMUR"
                  }
                  PositionSensor {
                    name "S_FL_FEMUR"
                  }
                ]
                endPoint Solid {
                  translation 0.06300000481925222 0 -2.5097711788164834e-08
                  rotation 0.9999999999999021 3.1293788071997465e-07 -3.1293903031750127e-07 1.5708000000000917
                  children [
                    HingeJoint {
                      jointParameters HingeJointParameters {
                        position -1.1562994308488656e-06
                        axis 0 0 1
                        anchor 0.04 -0.0095 0
                      }
                      device [
                        RotationalMotor {
                          name "M_FL_TIBIA"
                        }
                        PositionSensor {
                          name "S_FL_TIBIA"
                        }
                      ]
                      endPoint Solid {
                        translation 0.06100194461882348 -0.05101227166849322 -2.7777597584321963e-06
                        rotation 4.2078954581031326e-07 0.7071062529819792 0.707107309390596 3.141589208532963
                        children [
                          TouchSensor {
                            translation 0 0.0015 0
                            name "FL"
                            boundingObject Group {
                              children [
                                Pose {
                                  translation -0.033 0 -0.02
                                  children [
                                    Box {
                                      size 0.01 0.01 0.08
                                    }
                                  ]
                                }
                              ]
                            }
                          }
                          DEF JointFT Pose {
                            translation 0.012 0 0.0354013
                            rotation 0.3243588663662829 0.3243588663662829 0.888584633908982 1.68865
                            children [
                              Shape {
                                appearance PBRAppearance {
                                  baseColor 0.101961 0.101961 0.101961
                                  roughness 1
                                  metalness 0.3
                                }
                                geometry Box {
                                  size 0.045 0.02 0.045
                                }
                              }
                            ]
                          }
                          DEF L_SHAPE_TIBIA Shape {
                            appearance PBRAppearance {
                              baseColor 0.513726 0.513726 0.513726
                              roughness 1
                              metalness 0.3
                            }
                            geometry Mesh {
                              url [
                                "../webotsSTL/left-tibia-webots.stl"
                              ]
                            }
                          }
                        ]
                        boundingObject Group {
                          children [
                            Pose {
                              translation -0.033 0 -0.02
                              children [
                                Box {
                                  size 0.01 0.01 0.08
                                }
                              ]
                            }
                          ]
                        }
                        physics Physics {
                          density -1
                          mass 0.8
                        }
                        linearVelocity -0.08383142381975152 0.007290627570800634 -0.12531983574668384
                        angularVelocity -0.028080792005826957 -0.33192475363464646 -0.0004581720963092715
                      }
                    }
                    DEF L_SHAPE_FEMUR Shape {
                      appearance PBRAppearance {
                        baseColor 0.505882 0.505882 0.505882
                        roughness 1
                        metalness 0.3
                      }
                      geometry Mesh {
                        url [
                          "../webotsSTL/left-femur-webots.stl"
                        ]
                      }
                    }
                  ]
                  boundingObject USE L_SHAPE_FEMUR
                  physics Physics {
                    density -1
                    mass 0.8
                  }
                  linearVelocity -0.1084380908895714 0.009419567804490861 -0.10388175189320599
                  angularVelocity -0.028050343882717682 -0.3318529108428989 -0.0004347550106038843
                }
              }
            ]
            name "solid(2)"
            boundingObject USE L_SHAPE_COXA
            physics Physics {
              density -1
              mass 0.8
            }
            linearVelocity -0.10711933260232076 0.009365717029487223 -0.08931277512877209
            angularVelocity -0.028021525888795057 -0.3317829757112239 -0.0004188332525753985
          }
        }
      ]
    }
    DEF Leg0BL Pose {
      translation -0.06 -0.08 0
      rotation 0 0 -1 2.35619
      children [
        DEF JointBC Pose {
          translation -0.008 0 0
          children [
            Shape {
              appearance PBRAppearance {
                baseColor 0.101961 0.101961 0.101961
                roughness 1
                metalness 0.3
              }
              geometry Box {
                size 0.045 0.02 0.045
              }
            }
          ]
        }
        HingeJoint {
          jointParameters HingeJointParameters {
            position -1.347207935975697e-06
            axis 0 0 -1
          }
          device [
            PositionSensor {
              name "S_BL_COXA"
            }
            RotationalMotor {
              name "M_BL_COXA"
            }
          ]
          endPoint Solid {
            translation 0.019999997471628037 0.002000025283558145 0
            rotation 0 0 1 1.3470517849909945e-06
            children [
              DEF JointCF Pose {
                translation 0.022 -1.67293e-08 -1.67294e-08
                rotation 0.5773509358554485 -0.5773509358554485 0.5773489358556708 2.0944
                children [
                  Shape {
                    appearance PBRAppearance {
                      baseColor 0.101961 0.101961 0.101961
                      roughness 1
                      metalness 0.3
                    }
                    geometry Box {
                      size 0.045 0.02 0.045
                    }
                  }
                ]
              }
              DEF L_SHAPE_COXA Shape {
                appearance PBRAppearance {
                  baseColor 0.54902 0.54902 0.54902
                  roughness 1
                  metalness 0.3
                }
                geometry Mesh {
                  url [
                    "../webotsSTL/left-coxa-webots.stl"
                  ]
                }
              }
              HingeJoint {
                jointParameters HingeJointParameters {
                  position 1.040777887720634e-06
                  axis 0 1 0
                  anchor 0.0229 0 -0.0077
                }
                device [
                  RotationalMotor {
                    name "M_BL_FEMUR"
                  }
                  PositionSensor {
                    name "S_BL_FEMUR"
                  }
                ]
                endPoint Solid {
                  translation 0.0630000080139673 0 -4.173519738571302e-08
                  rotation 0.9999999999997291 5.203870325254227e-07 -5.203889437228402e-07 1.5708000000002615
                  children [
                    HingeJoint {
                      jointParameters HingeJointParameters {
                        position -1.4807743747884897e-06
                        axis 0 0 1
                        anchor 0.04 -0.0095 0
                      }
                      device [
                        RotationalMotor {
                          name "M_BL_TIBIA"
                        }
                        PositionSensor {
                          name "S_BL_TIBIA"
                        }
                      ]
                      endPoint Solid {
                        translation 0.06100186376318343 -0.051012278422201955 1.1485703175773124e-06
                        rotation 5.052281696865195e-07 0.7071063104187485 0.7071072519538526 3.141588923106322
                        children [
                          TouchSensor {
                            translation 0 0.0015 0
                            name "BL"
                            boundingObject Group {
                              children [
                                Pose {
                                  translation -0.033 0 -0.02
                                  children [
                                    Box {
                                      size 0.01 0.01 0.08
                                    }
                                  ]
                                }
                              ]
                            }
                          }
                          DEF JointFT Pose {
                            translation 0.012 0 0.0354013
                            rotation 0.3243588663662829 0.3243588663662829 0.888584633908982 1.68865
                            children [
                              Shape {
                                appearance PBRAppearance {
                                  baseColor 0.101961 0.101961 0.101961
                                  roughness 1
                                  metalness 0.3
                                }
                                geometry Box {
                                  size 0.045 0.02 0.045
                                }
                              }
                            ]
                          }
                          DEF L_SHAPE_TIBIA Shape {
                            appearance PBRAppearance {
                              baseColor 0.513726 0.513726 0.513726
                              roughness 1
                              metalness 0.3
                            }
                            geometry Mesh {
                              url [
                                "../webotsSTL/left-tibia-webots.stl"
                              ]
                            }
                          }
                        ]
                        boundingObject Group {
                          children [
                            Pose {
                              translation -0.033 0 -0.02
                              children [
                                Box {
                                  size 0.01 0.01 0.08
                                }
                              ]
                            }
                          ]
                        }
                        physics Physics {
                          density -1
                          mass 0.8
                        }
                        linearVelocity -0.0838558779421191 0.007335576324163356 -0.12488758167088293
                        angularVelocity -0.02812481499120322 -0.33196068666746037 -0.0005547962349536848
                      }
                    }
                    DEF L_SHAPE_FEMUR Shape {
                      appearance PBRAppearance {
                        baseColor 0.505882 0.505882 0.505882
                        roughness 1
                        metalness 0.3
                      }
                      geometry Mesh {
                        url [
                          "../webotsSTL/left-femur-webots.stl"
                        ]
                      }
                    }
                  ]
                  boundingObject USE L_SHAPE_FEMUR
                  physics Physics {
                    density -1
                    mass 0.8
                  }
                  linearVelocity -0.10845338609757212 0.009448583739237968 -0.1031398728275859
                  angularVelocity -0.028095851157152484 -0.33187615223642575 -0.000532072730963614
                }
              }
            ]
            name "solid(1)"
            boundingObject USE L_SHAPE_COXA
            physics Physics {
              density -1
              mass 0.8
            }
            linearVelocity -0.1071505953929716 0.009381017980804885 -0.08907917412897895
            angularVelocity -0.02806588796366201 -0.33179314109623487 -0.0005128312352375413
          }
        }
      ]
    }
    DEF Leg0ML Pose {
      translation -0.08 0 0
      rotation 0 0 -1 3.14159
      children [
        DEF JointBC Pose {
          translation -0.008 0 0
          children [
            Shape {
              appearance PBRAppearance {
                baseColor 0.101961 0.101961 0.101961
                roughness 1
                metalness 0.3
              }
              geometry Box {
                size 0.045 0.02 0.045
              }
            }
          ]
        }
        HingeJoint {
          jointParameters HingeJointParameters {
            position -1.0075271219687705e-06
            axis 0 0 -1
          }
          device [
            PositionSensor {
              name "S_ML_COXA"
            }
            RotationalMotor {
              name "M_ML_COXA"
            }
          ]
          endPoint Solid {
            translation 0.019999998150997223 0.002000018489942625 0
            rotation 0 0 1 1.0075653496013371e-06
            children [
              DEF JointCF Pose {
                translation 0.022 -1.67293e-08 -1.67294e-08
                rotation 0.5773509358554485 -0.5773509358554485 0.5773489358556708 2.0944
                children [
                  Shape {
                    appearance PBRAppearance {
                      baseColor 0.101961 0.101961 0.101961
                      roughness 1
                      metalness 0.3
                    }
                    geometry Box {
                      size 0.045 0.02 0.045
                    }
                  }
                ]
              }
              DEF L_SHAPE_COXA Shape {
                appearance PBRAppearance {
                  baseColor 0.54902 0.54902 0.54902
                  roughness 1
                  metalness 0.3
                }
                geometry Mesh {
                  url [
                    "../webotsSTL/left-coxa-webots.stl"
                  ]
                }
              }
              HingeJoint {
                jointParameters HingeJointParameters {
                  position 2.4579088913357706e-06
                  axis 0 1 0
                  anchor 0.0229 0 -0.0077
                }
                device [
                  RotationalMotor {
                    name "M_ML_FEMUR"
                  }
                  PositionSensor {
                    name "S_ML_FEMUR"
                  }
                ]
                endPoint Solid {
                  translation 0.06300001892577636 0 -9.856216974697685e-08
                  rotation 0.9999999999984897 1.2289499313946947e-06 -1.228954445746379e-06 1.5708000000015085
                  children [
                    HingeJoint {
                      jointParameters HingeJointParameters {
                        position -0.0010140302000815778
                        axis 0 0 1
                        anchor 0.04 -0.0095 0
                      }
                      device [
                        RotationalMotor {
                          name "M_ML_TIBIA"
                        }
                        PositionSensor {
                          name "S_ML_TIBIA"
                        }
                      ]
                      endPoint Solid {
                        translation 0.06096066631334107 -0.05103352310238006 -8.008652091218146e-07
                        rotation 0.00035850981052732 0.7071062367957222 0.7071072346930894 3.140872971137124
                        children [
                          TouchSensor {
                            translation 0 0.0015 0
                            name "ML"
                            boundingObject Group {
                              children [
                                Pose {
                                  translation -0.033 0 -0.02
                                  children [
                                    Box {
                                      size 0.01 0.01 0.08
                                    }
                                  ]
                                }
                              ]
                            }
                          }
                          DEF JointFT Pose {
                            translation 0.012 0 0.0354013
                            rotation 0.3243588663662829 0.3243588663662829 0.888584633908982 1.68865
                            children [
                              Shape {
                                appearance PBRAppearance {
                                  baseColor 0.101961 0.101961 0.101961
                                  roughness 1
                                  metalness 0.3
                                }
                                geometry Box {
                                  size 0.045 0.02 0.045
                                }
                              }
                            ]
                          }
                          DEF L_SHAPE_TIBIA Shape {
                            appearance PBRAppearance {
                              baseColor 0.513726 0.513726 0.513726
                              roughness 1
                              metalness 0.3
                            }
                            geometry Mesh {
                              url [
                                "../webotsSTL/left-tibia-webots.stl"
                              ]
                            }
                          }
                        ]
                        boundingObject Group {
                          children [
                            Pose {
                              translation -0.033 0 -0.02
                              children [
                                Box {
                                  size 0.01 0.01 0.08
                                }
                              ]
                            }
                          ]
                        }
                        physics Physics {
                          density -1
                          mass 0.8
                        }
                        linearVelocity -0.08282735918615032 0.007876116687512464 -0.14915313650240733
                        angularVelocity -0.030904706934885225 -0.3634238124214785 -0.00033205214705373453
                      }
                    }
                    DEF L_SHAPE_FEMUR Shape {
                      appearance PBRAppearance {
                        baseColor 0.505882 0.505882 0.505882
                        roughness 1
                        metalness 0.3
                      }
                      geometry Mesh {
                        url [
                          "../webotsSTL/left-femur-webots.stl"
                        ]
                      }
                    }
                  ]
                  boundingObject USE L_SHAPE_FEMUR
                  physics Physics {
                    density -1
                    mass 0.8
                  }
                  linearVelocity -0.10904321425363221 0.009925920531058665 -0.11724258439318228
                  angularVelocity -0.02793718140202412 -0.3318357223215451 -0.0003783822684737953
                }
              }
            ]
            name "solid(3)"
            boundingObject USE L_SHAPE_COXA
            physics Physics {
              density -1
              mass 0.8
            }
            linearVelocity -0.10744305988722175 0.00962412528460888 -0.09729369364875773
            angularVelocity -0.02797489397092251 -0.3317681044137775 -0.0004121875699889853
          }
        }
      ]
    }
    DEF Leg0MR Pose {
      translation 0.08 0 0
      children [
        DEF JointBC Pose {
          translation -0.008 0 0
          children [
            Shape {
              appearance PBRAppearance {
                baseColor 0.101961 0.101961 0.101961
                roughness 1
                metalness 0.3
              }
              geometry Box {
                size 0.045 0.02 0.045
              }
            }
          ]
        }
        HingeJoint {
          jointParameters HingeJointParameters {
            position -3.2649145070438734e-06
            axis 0 0 -1
          }
          device [
            PositionSensor {
              name "S_MR_COXA"
            }
            RotationalMotor {
              name "M_MR_COXA"
            }
          ]
          endPoint Solid {
            translation 0.019999745424528786 -0.0019998503533862053 1.1721242531390065e-05
            rotation -0.003885188251641994 -0.6611902845023964 0.7502081797687156 7.416288614827027e-06
            children [
              DEF JointCF Pose {
                translation 0.022 -1.67293e-08 -1.67294e-08
                rotation 0.5773509358554485 -0.5773509358554485 0.5773489358556708 2.0944
                children [
                  Shape {
                    appearance PBRAppearance {
                      baseColor 0.101961 0.101961 0.101961
                      roughness 1
                      metalness 0.3
                    }
                    geometry Box {
                      size 0.045 0.02 0.045
                    }
                  }
                ]
              }
              DEF R_SHAPE_COXA Shape {
                appearance PBRAppearance {
                  baseColor 0.54902 0.54902 0.54902
                  roughness 1
                  metalness 0.3
                }
                geometry Mesh {
                  url [
                    "../webotsSTL/right-coxa-webots.stl"
                  ]
                }
              }
              HingeJoint {
                jointParameters HingeJointParameters {
                  position 7.235063452791986e-07
                  axis 0 -1 0
                  anchor 0.0229 0 -0.0077
                }
                device [
                  RotationalMotor {
                    name "M_MR_FEMUR"
                  }
                  PositionSensor {
                    name "S_MR_FEMUR"
                  }
                ]
                endPoint Solid {
                  translation 0.06299999442898989 0 2.9012602392568254e-08
                  rotation -0.9999999999999895 -1.422435417265434e-07 2.9025827450872315e-08 1.5707953071796434
                  children [
                    HingeJoint {
                      jointParameters HingeJointParameters {
                        position -1.3717681811330052e-06
                        axis 0 0 1
                        anchor 0.041 0.008 0
                      }
                      device [
                        RotationalMotor {
                          name "M_MR_TIBIA"
                        }
                        PositionSensor {
                          name "S_MR_TIBIA"
                        }
                      ]
                      endPoint Solid {
                        translation 0.05602726282573308 0.047970145402618354 2.3798995164803226e-05
                        rotation -2.39049297601815e-07 -0.707107917025023 0.7071056453462073 3.1415896742165432
                        children [
                          TouchSensor {
                            translation 0 -0.0015 0
                            name "MR"
                            boundingObject Group {
                              children [
                                Pose {
                                  translation -0.033 0 -0.02
                                  children [
                                    Box {
                                      size 0.01 0.01 0.08
                                    }
                                  ]
                                }
                              ]
                            }
                          }
                          DEF JointFT Pose {
                            translation 0.0118 0 0.035
                            rotation 0.3243588663662829 0.3243588663662829 0.888584633908982 1.68865
                            children [
                              Shape {
                                appearance PBRAppearance {
                                  baseColor 0.101961 0.101961 0.101961
                                  roughness 1
                                  metalness 0.3
                                }
                                geometry Box {
                                  size 0.045 0.02 0.045
                                }
                              }
                            ]
                          }
                          DEF R_SHAPE_TIBIA Shape {
                            appearance PBRAppearance {
                              baseColor 0.513726 0.513726 0.513726
                              roughness 1
                              metalness 0.3
                            }
                            geometry Mesh {
                              url [
                                "../webotsSTL/right-tibia-webots.stl"
                              ]
                            }
                          }
                        ]
                        boundingObject Group {
                          children [
                            Pose {
                              translation -0.033 0 -0.02
                              children [
                                Box {
                                  size 0.01 0.01 0.08
                                }
                              ]
                            }
                          ]
                        }
                        physics Physics {
                          density -1
                          mass 0.8
                        }
                        linearVelocity -0.08363188816161736 0.00730149697712676 0.019969628943695028
                        angularVelocity -0.028008534744707395 -0.3316589575567114 -0.0005002015678086057
                      }
                    }
                    DEF R_SHAPE_FEMUR Shape {
                      appearance PBRAppearance {
                        baseColor 0.505882 0.505882 0.505882
                        roughness 1
                        metalness 0.3
                      }
                      geometry Mesh {
                        url [
                          "../webotsSTL/right-femur-webots.stl"
                        ]
                      }
                    }
                  ]
                  boundingObject USE R_SHAPE_FEMUR
                  physics Physics {
                    density -1
                    mass 0.8
                  }
                  linearVelocity -0.10736859591162701 0.009349507548436673 -0.00871618319294086
                  angularVelocity -0.02800984280149352 -0.3316725965955151 -0.0005002086635174765
                }
              }
            ]
            boundingObject USE R_SHAPE_COXA
            physics Physics {
              density -1
              mass 0.8
            }
            linearVelocity -0.10664206781051505 0.009319132028962996 -0.029009138259041195
            angularVelocity -0.028013686034497325 -0.33171192419265383 -0.0005002676372284761
          }
        }
      ]
    }
    DEF Body Pose {
      children [
        Shape {
          appearance PBRAppearance {
            baseColor 0.533333 0.533333 0.533333
            roughness 1
            metalness 0.3
          }
          geometry Mesh {
            url [
              "../webotsSTL/frame-webots.stl"
            ]
          }
        }
      ]
    }
  ]
  name "Hexapod"
  boundingObject Box {
    size 0.17 0.2 0.02
  }
  physics Physics {
    density 500
  }
  controller "new_hexapod"
  linearVelocity -0.10690296922550915 0.009389396885402527 -0.06327310751929849
  angularVelocity -0.028015758960019656 -0.33173310424384284 -0.00045046608218278
}
