#VRML_SIM R2023b utf8

EXTERNPROTO "https://raw.githubusercontent.com/cyberbotics/webots/R2023b/projects/objects/backgrounds/protos/TexturedBackground.proto"
EXTERNPROTO "https://raw.githubusercontent.com/cyberbotics/webots/R2023b/projects/objects/backgrounds/protos/TexturedBackgroundLight.proto"
EXTERNPROTO "https://raw.githubusercontent.com/cyberbotics/webots/R2023b/projects/objects/floors/protos/RectangleArena.proto"
EXTERNPROTO "https://raw.githubusercontent.com/cyberbotics/webots/R2023b/projects/appearances/protos/Parquetry.proto"

WorldInfo {
}
Viewpoint {
  orientation 0.027239185632813724 0.028466395402797665 -0.9992235441075398 3.2047662224117186
  position 1.7685954055195081 0.9446591131130629 0.17857678850490818
  follow "Hexapod"
}
TexturedBackground {
}
RectangleArena {
  translation 0 -0.02 0
  floorSize 10 10
  floorAppearance Parquetry {
    type "light strip"
  }
}
TexturedBackgroundLight {
}
Pose {
  translation -0.83 0 0
  children [
    Group {
      children [
        Solid {
          translation -0.019933880692263206 -0.039987297428865046 0.049607600000000064
          rotation 1.1937949593298407e-12 7.664632200489308e-13 -1 5.076325663243499e-05
          children [
            DEF BOX Shape {
              appearance PBRAppearance {
              }
              geometry Box {
                size 0.1 0.1 0.1
              }
            }
          ]
          boundingObject USE BOX
          physics Physics {
          }
          linearVelocity -1.343294870414435e-17 -1.498170655321142e-17 -4.55008175271314e-16
          angularVelocity 2.664535259100376e-16 -5.329070518200752e-16 -1.1057753825179877e-16
        }
        Solid {
          translation 0.06990678014426754 -0.19993550478438063 0.04960760000000006
          rotation -5.222790214196923e-13 -1.232181570597494e-12 0.9999999999999999 9.93191651368193e-05
          children [
            DEF BOX Shape {
              appearance PBRAppearance {
              }
              geometry Box {
                size 0.1 0.1 0.1
              }
            }
          ]
          name "solid(1)"
          boundingObject USE BOX
          physics Physics {
          }
          linearVelocity 1.7635452024700637e-17 4.245401389297274e-17 -3.9811329061514897e-16
          angularVelocity -7.99360577730113e-16 2.664535259100374e-16 -1.404884981222987e-16
        }
        Solid {
          translation 0.30173801120117993 -0.1900167535377724 0.04960760000000007
          rotation -4.2803172901567085e-13 1.8112056581693833e-13 1 0.00019245914347985858
          children [
            DEF BOX Shape {
              appearance PBRAppearance {
              }
              geometry Box {
                size 0.1 0.1 0.1
              }
            }
          ]
          name "solid(2)"
          boundingObject USE BOX
          physics Physics {
          }
          linearVelocity 1.5282440725932608e-17 -2.2783736496510164e-17 -3.979837835343933e-16
          angularVelocity 3.996802888650577e-16 2.66453525910037e-16 -2.1717749539223384e-16
        }
        Solid {
          translation 0.96135 0.72211 0.029814
          rotation 0.9999976553337651 -0.0002780579041626044 -0.0021475592598071 0.2618
          children [
            DEF BOX Shape {
              appearance PBRAppearance {
              }
              geometry Box {
                size 1.1 1.2 0.01
              }
            }
          ]
          name "solid(3)"
          boundingObject USE BOX
        }
        Solid {
          translation -0.020051649108723035 0.15992621635509713 0.049607600000000064
          rotation 8.315320180465853e-13 -2.1942458933654825e-13 -1 0.00017334433090591237
          children [
            DEF BOX Shape {
              appearance PBRAppearance {
              }
              geometry Box {
                size 0.1 0.1 0.1
              }
            }
          ]
          name "solid(4)"
          boundingObject USE BOX
          physics Physics {
          }
          linearVelocity 3.469790939398027e-17 -3.229217317009731e-17 -4.549598915165724e-16
          angularVelocity 1.0658141036401493e-15 5.329070518200752e-16 1.572294436097922e-16
        }
        Solid {
          translation 0.1890043893105372 0.02158301782354741 0.049607600000000064
          rotation -3.537831197469979e-15 -3.354503297777566e-15 -1 0.020179439358772866
          children [
            DEF BOX Shape {
              appearance PBRAppearance {
              }
              geometry Box {
                size 0.1 0.1 0.1
              }
            }
          ]
          name "solid(5)"
          boundingObject USE BOX
          physics Physics {
          }
          linearVelocity 5.68840105485836e-17 -3.712889710347833e-17 -4.549052523989339e-16
          angularVelocity 6.661338147750856e-16 1.3322676295486803e-15 1.750862042103601e-17
        }
      ]
    }
  ]
}
Robot {
  translation 0.2600238279441773 0.9933888054794169 0.2158672680737569
  rotation 0.059855118640341945 0.06347697178535577 -0.996186748971051 1.6221660496692911
  children [
    InertialUnit {
      children [
        Shape {
          geometry Cylinder {
            height 0.02
            radius 0.03
          }
        }
      ]
      name "imu"
    }
    DEF Leg0FR Pose {
      translation 0.063 0.082 0
      rotation 0 0 1 0.785398
      children [
        DEF JointBC Pose {
          translation -0.008 0 0
          children [
            Shape {
              appearance PBRAppearance {
                baseColor 0.101961 0.101961 0.101961
                roughness 1
                metalness 0.3
              }
              geometry Box {
                size 0.045 0.02 0.045
              }
            }
          ]
        }
        HingeJoint {
          jointParameters HingeJointParameters {
            position -0.03651141153038728
            axis 0 0 -1
          }
          device [
            PositionSensor {
              name "S_FR_COXA"
            }
            RotationalMotor {
              name "M_FR_COXA"
            }
          ]
          endPoint Solid {
            translation 0.02005967724903309 -0.0012686010659868137 0
            rotation 0 0 1 0.03651141153038944
            children [
              DEF JointCF Pose {
                translation 0.022 -1.67293e-08 -1.67294e-08
                rotation 0.5773509358554485 -0.5773509358554485 0.5773489358556708 2.0944
                children [
                  Shape {
                    appearance PBRAppearance {
                      baseColor 0.101961 0.101961 0.101961
                      roughness 1
                      metalness 0.3
                    }
                    geometry Box {
                      size 0.045 0.02 0.045
                    }
                  }
                ]
              }
              DEF R_SHAPE_COXA Shape {
                appearance PBRAppearance {
                  baseColor 0.54902 0.54902 0.54902
                  roughness 1
                  metalness 0.3
                }
                geometry Mesh {
                  url [
                    "../webotsSTL/right-coxa-webots.stl"
                  ]
                }
              }
              HingeJoint {
                jointParameters HingeJointParameters {
                  position -0.2559614104543807
                  axis 0 -1 0
                  anchor 0.0229 0 -0.0077
                }
                device [
                  RotationalMotor {
                    name "M_FR_FEMUR"
                  }
                  PositionSensor {
                    name "S_FR_FEMUR"
                  }
                ]
                endPoint Solid {
                  translation 0.06364300774354671 0 -0.01040320550628959
                  rotation -0.9838406200794113 0.12660494520734056 0.12660498462069253 1.5870859311938095
                  children [
                    HingeJoint {
                      jointParameters HingeJointParameters {
                        position -0.1822671656779014
                        axis 0 0 1
                        anchor 0.041 0.008 0
                      }
                      device [
                        RotationalMotor {
                          name "M_FR_TIBIA"
                        }
                        PositionSensor {
                          name "S_FR_TIBIA"
                        }
                      ]
                      endPoint Solid {
                        translation 0.0630226019988218 0.04457157733262491 2.4767050973366087e-05
                        rotation -0.06448581088597012 -0.7056365836580363 0.7056334685924373 3.0127972608806055
                        children [
                          DEF JointFT Pose {
                            translation 0.0118 0 0.035
                            rotation 0.3243588663662829 0.3243588663662829 0.888584633908982 1.68865
                            children [
                              Shape {
                                appearance PBRAppearance {
                                  baseColor 0.101961 0.101961 0.101961
                                  roughness 1
                                  metalness 0.3
                                }
                                geometry Box {
                                  size 0.045 0.02 0.045
                                }
                              }
                            ]
                          }
                          DEF R_SHAPE_TIBIA Shape {
                            appearance PBRAppearance {
                              baseColor 0.513726 0.513726 0.513726
                              roughness 1
                              metalness 0.3
                            }
                            geometry Mesh {
                              url [
                                "../webotsSTL/right-tibia-webots.stl"
                              ]
                            }
                          }
                        ]
                        boundingObject Group {
                          children [
                            Pose {
                              translation -0.033 0 -0.02
                              children [
                                Box {
                                  size 0.01 0.01 0.08
                                }
                              ]
                            }
                          ]
                        }
                        physics Physics {
                          density -1
                          mass 0.8
                        }
                        linearVelocity 1.113183560967987e-07 2.8238530410790692e-06 -3.346000817545358e-05
                        angularVelocity 6.244214971900208e-05 0.00011940670923146353 -3.3649739813930104e-05
                      }
                    }
                    DEF R_SHAPE_FEMUR Shape {
                      appearance PBRAppearance {
                        baseColor 0.505882 0.505882 0.505882
                        roughness 1
                        metalness 0.3
                      }
                      geometry Mesh {
                        url [
                          "../webotsSTL/right-femur-webots.stl"
                        ]
                      }
                    }
                  ]
                  boundingObject USE R_SHAPE_FEMUR
                  physics Physics {
                    density -1
                    mass 0.8
                  }
                  linearVelocity 1.8733865373461154e-05 -1.2418205949864556e-05 -1.5150287129518865e-05
                  angularVelocity 0.0003089521768454964 0.0003570477278405876 -3.651423103782994e-06
                }
              }
            ]
            name "solid(5)"
            boundingObject USE R_SHAPE_COXA
            physics Physics {
              density -1
              mass 0.8
            }
            linearVelocity 2.3247508106182318e-05 -1.8339270429664984e-05 4.2551272672490625e-06
            angularVelocity 9.434874318411458e-06 6.925557913401136e-05 -4.0220281419498895e-05
          }
        }
      ]
    }
    DEF Leg0BR Pose {
      translation 0.06 -0.08 0
      rotation 0 0 1 -0.785395307179586
      children [
        DEF JointBC Pose {
          translation -0.008 0 0
          children [
            Shape {
              appearance PBRAppearance {
                baseColor 0.101961 0.101961 0.101961
                roughness 1
                metalness 0.3
              }
              geometry Box {
                size 0.045 0.02 0.045
              }
            }
          ]
        }
        HingeJoint {
          jointParameters HingeJointParameters {
            position 0.08111647007710122
            axis 0 0 -1
          }
          device [
            PositionSensor {
              name "S_BR_COXA"
            }
            RotationalMotor {
              name "M_BR_COXA"
            }
          ]
          endPoint Solid {
            translation 0.019772182167528633 -0.0036139745895708703 0
            rotation 0 0 -1 0.0811164700770987
            children [
              DEF JointCF Pose {
                translation 0.022 -1.67293e-08 -1.67294e-08
                rotation 0.5773509358554485 -0.5773509358554485 0.5773489358556708 2.0944
                children [
                  Shape {
                    appearance PBRAppearance {
                      baseColor 0.101961 0.101961 0.101961
                      roughness 1
                      metalness 0.3
                    }
                    geometry Box {
                      size 0.045 0.02 0.045
                    }
                  }
                ]
              }
              DEF R_SHAPE_COXA Shape {
                appearance PBRAppearance {
                  baseColor 0.54902 0.54902 0.54902
                  roughness 1
                  metalness 0.3
                }
                geometry Mesh {
                  url [
                    "../webotsSTL/right-coxa-webots.stl"
                  ]
                }
              }
              HingeJoint {
                jointParameters HingeJointParameters {
                  position -0.20796320966991566
                  axis 0 -1 0
                  anchor 0.0229 0 -0.0077
                }
                device [
                  RotationalMotor {
                    name "M_BR_FEMUR"
                  }
                  PositionSensor {
                    name "S_BR_FEMUR"
                  }
                ]
                endPoint Solid {
                  translation 0.06372578351339014 0 -0.008445251982712156
                  rotation -0.9892840755528727 0.10324002278163102 0.10324008695049852 1.5815688344116314
                  children [
                    HingeJoint {
                      jointParameters HingeJointParameters {
                        position -0.13815214136768011
                        axis 0 0 1
                        anchor 0.041 0.008 0
                      }
                      device [
                        RotationalMotor {
                          name "M_BR_TIBIA"
                        }
                        PositionSensor {
                          name "S_BR_TIBIA"
                        }
                      ]
                      endPoint Solid {
                        translation 0.06138834321916882 0.045507209016028664 2.4767050973366236e-05
                        rotation -0.04886365730729029 -0.706263656628007 0.7062605682897726 3.0439407702771626
                        children [
                          DEF JointFT Pose {
                            translation 0.0118 0 0.035
                            rotation 0.3243588663662829 0.3243588663662829 0.888584633908982 1.68865
                            children [
                              Shape {
                                appearance PBRAppearance {
                                  baseColor 0.101961 0.101961 0.101961
                                  roughness 1
                                  metalness 0.3
                                }
                                geometry Box {
                                  size 0.045 0.02 0.045
                                }
                              }
                            ]
                          }
                          DEF R_SHAPE_TIBIA Shape {
                            appearance PBRAppearance {
                              baseColor 0.513726 0.513726 0.513726
                              roughness 1
                              metalness 0.3
                            }
                            geometry Mesh {
                              url [
                                "../webotsSTL/right-tibia-webots.stl"
                              ]
                            }
                          }
                        ]
                        boundingObject Group {
                          children [
                            Pose {
                              translation -0.033 0 -0.02
                              children [
                                Box {
                                  size 0.01 0.01 0.08
                                }
                              ]
                            }
                          ]
                        }
                        physics Physics {
                          density -1
                          mass 0.8
                        }
                        linearVelocity 2.1580684335124233e-05 -1.1785255631160889e-05 5.92276985432188e-05
                        angularVelocity -3.519428206630422e-05 0.00012914554603355534 -4.462136440756522e-05
                      }
                    }
                    DEF R_SHAPE_FEMUR Shape {
                      appearance PBRAppearance {
                        baseColor 0.505882 0.505882 0.505882
                        roughness 1
                        metalness 0.3
                      }
                      geometry Mesh {
                        url [
                          "../webotsSTL/right-femur-webots.stl"
                        ]
                      }
                    }
                  ]
                  boundingObject USE R_SHAPE_FEMUR
                  physics Physics {
                    density -1
                    mass 0.8
                  }
                  linearVelocity 3.31644200740282e-05 -1.3262149916126906e-05 3.762675350003063e-05
                  angularVelocity -0.00020649911675756842 0.00035193339653017005 -1.6061886164543337e-05
                }
              }
            ]
            name "solid(4)"
            boundingObject USE R_SHAPE_COXA
            physics Physics {
              density -1
              mass 0.8
            }
            linearVelocity 2.9506419355823147e-05 -2.0716944128614105e-05 1.6756294845663825e-05
            angularVelocity 9.578687067237077e-06 7.019836835092507e-05 -5.165760433255144e-05
          }
        }
      ]
    }
    DEF Leg0FL Pose {
      translation -0.063 0.082 0
      rotation 0 0 1 2.3562
      children [
        DEF JointBC Pose {
          translation -0.008 0 0
          children [
            Shape {
              appearance PBRAppearance {
                baseColor 0.101961 0.101961 0.101961
                roughness 1
                metalness 0.3
              }
              geometry Box {
                size 0.045 0.02 0.045
              }
            }
          ]
        }
        HingeJoint {
          jointParameters HingeJointParameters {
            position -0.028894657915268927
            axis 0 0 -1
          }
          device [
            PositionSensor {
              name "S_FL_COXA"
            }
            RotationalMotor {
              name "M_FL_COXA"
            }
          ]
          endPoint Solid {
            translation 0.019933870507502345 0.002576976249430687 0
            rotation 0 0 1 0.02889465791527417
            children [
              DEF JointCF Pose {
                translation 0.022 -1.67293e-08 -1.67294e-08
                rotation 0.5773509358554485 -0.5773509358554485 0.5773489358556708 2.0944
                children [
                  Shape {
                    appearance PBRAppearance {
                      baseColor 0.101961 0.101961 0.101961
                      roughness 1
                      metalness 0.3
                    }
                    geometry Box {
                      size 0.045 0.02 0.045
                    }
                  }
                ]
              }
              DEF L_SHAPE_COXA Shape {
                appearance PBRAppearance {
                  baseColor 0.54902 0.54902 0.54902
                  roughness 1
                  metalness 0.3
                }
                geometry Mesh {
                  url [
                    "../webotsSTL/left-coxa-webots.stl"
                  ]
                }
              }
              HingeJoint {
                jointParameters HingeJointParameters {
                  position -0.2957980075951635
                  axis 0 1 0
                  anchor 0.0229 0 -0.0077
                }
                device [
                  RotationalMotor {
                    name "M_FL_FEMUR"
                  }
                  PositionSensor {
                    name "S_FL_FEMUR"
                  }
                ]
                endPoint Solid {
                  translation 0.05901387463093939 0 0.011354869696240893
                  rotation 0.9785157232282988 -0.14578549869267865 0.14578603419369912 1.592516715511076
                  children [
                    HingeJoint {
                      jointParameters HingeJointParameters {
                        position -0.18102127954870761
                        axis 0 0 1
                        anchor 0.04 -0.0095 0
                      }
                      device [
                        RotationalMotor {
                          name "M_FL_TIBIA"
                        }
                        PositionSensor {
                          name "S_FL_TIBIA"
                        }
                      ]
                      endPoint Solid {
                        translation 0.05318544538830759 -0.054102623576555764 -8.485299999999875e-07
                        rotation 0.06404423731421906 0.70565469504744 0.705655572517035 3.0136760500773385
                        children [
                          DEF JointFT Pose {
                            translation 0.012 0 0.0354013
                            rotation 0.3243588663662829 0.3243588663662829 0.888584633908982 1.68865
                            children [
                              Shape {
                                appearance PBRAppearance {
                                  baseColor 0.101961 0.101961 0.101961
                                  roughness 1
                                  metalness 0.3
                                }
                                geometry Box {
                                  size 0.045 0.02 0.045
                                }
                              }
                            ]
                          }
                          DEF L_SHAPE_TIBIA Shape {
                            appearance PBRAppearance {
                              baseColor 0.513726 0.513726 0.513726
                              roughness 1
                              metalness 0.3
                            }
                            geometry Mesh {
                              url [
                                "../webotsSTL/left-tibia-webots.stl"
                              ]
                            }
                          }
                        ]
                        boundingObject Group {
                          children [
                            Pose {
                              translation -0.033 0 -0.02
                              children [
                                Box {
                                  size 0.01 0.01 0.08
                                }
                              ]
                            }
                          ]
                        }
                        physics Physics {
                          density -1
                          mass 0.8
                        }
                        linearVelocity -1.0914505963273022e-05 -3.684843472110591e-05 -3.513569785412299e-05
                        angularVelocity -9.602306800056789e-05 0.00015893159495068655 0.0001009358876312189
                      }
                    }
                    DEF L_SHAPE_FEMUR Shape {
                      appearance PBRAppearance {
                        baseColor 0.505882 0.505882 0.505882
                        roughness 1
                        metalness 0.3
                      }
                      geometry Mesh {
                        url [
                          "../webotsSTL/left-femur-webots.stl"
                        ]
                      }
                    }
                  ]
                  boundingObject USE L_SHAPE_FEMUR
                  physics Physics {
                    density -1
                    mass 0.8
                  }
                  linearVelocity 1.0648858340739875e-05 -3.059268816439765e-05 -1.0574609733915377e-05
                  angularVelocity -0.0001688268917476238 0.00023339187783251748 0.00011054385862702392
                }
              }
            ]
            name "solid(2)"
            boundingObject USE L_SHAPE_COXA
            physics Physics {
              density -1
              mass 0.8
            }
            linearVelocity 1.4804922272315422e-05 -2.9924175468405803e-05 1.9348429540094544e-06
            angularVelocity 8.19903011310352e-06 5.347410765019096e-05 8.781931302836619e-05
          }
        }
      ]
    }
    DEF Leg0BL Pose {
      translation -0.06 -0.08 0
      rotation 0 0 -1 2.35619
      children [
        DEF JointBC Pose {
          translation -0.008 0 0
          children [
            Shape {
              appearance PBRAppearance {
                baseColor 0.101961 0.101961 0.101961
                roughness 1
                metalness 0.3
              }
              geometry Box {
                size 0.045 0.02 0.045
              }
            }
          ]
        }
        HingeJoint {
          jointParameters HingeJointParameters {
            position 0.05935247675733627
            axis 0 0 -1
          }
          device [
            PositionSensor {
              name "S_BL_COXA"
            }
            RotationalMotor {
              name "M_BL_COXA"
            }
          ]
          endPoint Solid {
            translation 0.02008341851416056 0.0008101239319213444 0
            rotation 0 0 -1 0.0593524767573393
            children [
              DEF JointCF Pose {
                translation 0.022 -1.67293e-08 -1.67294e-08
                rotation 0.5773509358554485 -0.5773509358554485 0.5773489358556708 2.0944
                children [
                  Shape {
                    appearance PBRAppearance {
                      baseColor 0.101961 0.101961 0.101961
                      roughness 1
                      metalness 0.3
                    }
                    geometry Box {
                      size 0.045 0.02 0.045
                    }
                  }
                ]
              }
              DEF L_SHAPE_COXA Shape {
                appearance PBRAppearance {
                  baseColor 0.54902 0.54902 0.54902
                  roughness 1
                  metalness 0.3
                }
                geometry Mesh {
                  url [
                    "../webotsSTL/left-coxa-webots.stl"
                  ]
                }
              }
              HingeJoint {
                jointParameters HingeJointParameters {
                  position -0.30727159239957663
                  axis 0 1 0
                  anchor 0.0229 0 -0.0077
                }
                device [
                  RotationalMotor {
                    name "M_BL_FEMUR"
                  }
                  PositionSensor {
                    name "S_BL_FEMUR"
                  }
                ]
                endPoint Solid {
                  translation 0.05879287471831761 0 0.0117679620005564
                  rotation 0.9768491653215382 -0.1512705194408041 0.15127107508946752 1.5942208818963775
                  children [
                    HingeJoint {
                      jointParameters HingeJointParameters {
                        position -0.1758460267629846
                        axis 0 0 1
                        anchor 0.04 -0.0095 0
                      }
                      device [
                        RotationalMotor {
                          name "M_BL_TIBIA"
                        }
                        PositionSensor {
                          name "S_BL_TIBIA"
                        }
                      ]
                      endPoint Solid {
                        translation 0.05341609763573954 -0.05403378856810054 -8.48529999999993e-07
                        rotation 0.062210882236064295 0.7057366940205166 0.7057375750549223 3.0173282092719127
                        children [
                          DEF JointFT Pose {
                            translation 0.012 0 0.0354013
                            rotation 0.3243588663662829 0.3243588663662829 0.888584633908982 1.68865
                            children [
                              Shape {
                                appearance PBRAppearance {
                                  baseColor 0.101961 0.101961 0.101961
                                  roughness 1
                                  metalness 0.3
                                }
                                geometry Box {
                                  size 0.045 0.02 0.045
                                }
                              }
                            ]
                          }
                          DEF L_SHAPE_TIBIA Shape {
                            appearance PBRAppearance {
                              baseColor 0.513726 0.513726 0.513726
                              roughness 1
                              metalness 0.3
                            }
                            geometry Mesh {
                              url [
                                "../webotsSTL/left-tibia-webots.stl"
                              ]
                            }
                          }
                        ]
                        boundingObject Group {
                          children [
                            Pose {
                              translation -0.033 0 -0.02
                              children [
                                Box {
                                  size 0.01 0.01 0.08
                                }
                              ]
                            }
                          ]
                        }
                        physics Physics {
                          density -1
                          mass 0.8
                        }
                        linearVelocity 1.990759829449424e-06 -4.128210816752288e-05 5.969265548018049e-05
                        angularVelocity 0.0001525728069350784 0.0001707168506754724 9.313530026374095e-05
                      }
                    }
                    DEF L_SHAPE_FEMUR Shape {
                      appearance PBRAppearance {
                        baseColor 0.505882 0.505882 0.505882
                        roughness 1
                        metalness 0.3
                      }
                      geometry Mesh {
                        url [
                          "../webotsSTL/left-femur-webots.stl"
                        ]
                      }
                    }
                  ]
                  boundingObject USE L_SHAPE_FEMUR
                  physics Physics {
                    density -1
                    mass 0.8
                  }
                  linearVelocity 1.9480227929207097e-05 -4.0518510373396297e-05 2.9489436636929062e-05
                  angularVelocity 0.00025717520093861764 0.00025519857024078357 0.00010362083174400916
                }
              }
            ]
            name "solid(1)"
            boundingObject USE L_SHAPE_COXA
            physics Physics {
              density -1
              mass 0.8
            }
            linearVelocity 1.858109171309022e-05 -2.9377026606276125e-05 1.579373107774031e-05
            angularVelocity 9.081250527808483e-06 5.4454623049255374e-05 7.785045379672098e-05
          }
        }
      ]
    }
    DEF Leg0ML Pose {
      translation -0.08 0 0
      rotation 0 0 -1 3.14159
      children [
        DEF JointBC Pose {
          translation -0.008 0 0
          children [
            Shape {
              appearance PBRAppearance {
                baseColor 0.101961 0.101961 0.101961
                roughness 1
                metalness 0.3
              }
              geometry Box {
                size 0.045 0.02 0.045
              }
            }
          ]
        }
        HingeJoint {
          jointParameters HingeJointParameters {
            position 0.013375395867129873
            axis 0 0 -1
          }
          device [
            PositionSensor {
              name "S_ML_COXA"
            }
            RotationalMotor {
              name "M_ML_COXA"
            }
          ]
          endPoint Solid {
            translation 0.020024961152476272 0.0017323194976156472 0
            rotation 0 0 -1 0.013375395867140025
            children [
              DEF JointCF Pose {
                translation 0.022 -1.67293e-08 -1.67294e-08
                rotation 0.5773509358554485 -0.5773509358554485 0.5773489358556708 2.0944
                children [
                  Shape {
                    appearance PBRAppearance {
                      baseColor 0.101961 0.101961 0.101961
                      roughness 1
                      metalness 0.3
                    }
                    geometry Box {
                      size 0.045 0.02 0.045
                    }
                  }
                ]
              }
              DEF L_SHAPE_COXA Shape {
                appearance PBRAppearance {
                  baseColor 0.54902 0.54902 0.54902
                  roughness 1
                  metalness 0.3
                }
                geometry Mesh {
                  url [
                    "../webotsSTL/left-coxa-webots.stl"
                  ]
                }
              }
              HingeJoint {
                jointParameters HingeJointParameters {
                  position -0.3924323465720086
                  axis 0 1 0
                  anchor 0.0229 0 -0.0077
                }
                device [
                  RotationalMotor {
                    name "M_ML_FEMUR"
                  }
                  PositionSensor {
                    name "S_ML_FEMUR"
                  }
                ]
                endPoint Solid {
                  translation 0.057006896343040694 0 0.014750381329612363
                  rotation 0.9626865648686183 -0.19135609320823144 0.1913567960997001 1.6088182335022938
                  children [
                    HingeJoint {
                      jointParameters HingeJointParameters {
                        position -0.21172123625414524
                        axis 0 0 1
                        anchor 0.04 -0.0095 0
                      }
                      device [
                        RotationalMotor {
                          name "M_ML_TIBIA"
                        }
                        PositionSensor {
                          name "S_ML_TIBIA"
                        }
                      ]
                      endPoint Solid {
                        translation 0.051810148786838865 -0.054486335543503926 -8.485299999999949e-07
                        rotation 0.07492440039165517 0.7051188292469521 0.7051196854913061 2.992020463674926
                        children [
                          DEF JointFT Pose {
                            translation 0.012 0 0.0354013
                            rotation 0.3243588663662829 0.3243588663662829 0.888584633908982 1.68865
                            children [
                              Shape {
                                appearance PBRAppearance {
                                  baseColor 0.101961 0.101961 0.101961
                                  roughness 1
                                  metalness 0.3
                                }
                                geometry Box {
                                  size 0.045 0.02 0.045
                                }
                              }
                            ]
                          }
                          DEF L_SHAPE_TIBIA Shape {
                            appearance PBRAppearance {
                              baseColor 0.513726 0.513726 0.513726
                              roughness 1
                              metalness 0.3
                            }
                            geometry Mesh {
                              url [
                                "../webotsSTL/left-tibia-webots.stl"
                              ]
                            }
                          }
                        ]
                        boundingObject Group {
                          children [
                            Pose {
                              translation -0.033 0 -0.02
                              children [
                                Box {
                                  size 0.01 0.01 0.08
                                }
                              ]
                            }
                          ]
                        }
                        physics Physics {
                          density -1
                          mass 0.8
                        }
                        linearVelocity 8.708942012394649e-06 -2.9279597070859143e-05 1.0898397433470878e-05
                        angularVelocity 3.528349650419855e-05 5.0666609638699805e-05 9.111600175873733e-05
                      }
                    }
                    DEF L_SHAPE_FEMUR Shape {
                      appearance PBRAppearance {
                        baseColor 0.505882 0.505882 0.505882
                        roughness 1
                        metalness 0.3
                      }
                      geometry Mesh {
                        url [
                          "../webotsSTL/left-femur-webots.stl"
                        ]
                      }
                    }
                  ]
                  boundingObject USE L_SHAPE_FEMUR
                  physics Physics {
                    density -1
                    mass 0.8
                  }
                  linearVelocity 1.902834708294993e-05 -2.933868999788889e-05 8.184065544441629e-06
                  angularVelocity 4.8822127353530067e-05 5.006008650857131e-05 9.108617319526548e-05
                }
              }
            ]
            name "solid(3)"
            boundingObject USE L_SHAPE_COXA
            physics Physics {
              density -1
              mass 0.8
            }
            linearVelocity 2.1002704124780624e-05 -2.643474140702634e-05 8.112483940044177e-06
            angularVelocity 8.66131647030641e-06 5.235249014718692e-05 9.16866647061133e-05
          }
        }
      ]
    }
    DEF Leg0MR Pose {
      translation 0.08 0 0
      children [
        DEF JointBC Pose {
          translation -0.008 0 0
          children [
            Shape {
              appearance PBRAppearance {
                baseColor 0.101961 0.101961 0.101961
                roughness 1
                metalness 0.3
              }
              geometry Box {
                size 0.045 0.02 0.045
              }
            }
          ]
        }
        HingeJoint {
          jointParameters HingeJointParameters {
            position 0.023576587770476956
            axis 0 0 -1
          }
          device [
            PositionSensor {
              name "S_MR_COXA"
            }
            RotationalMotor {
              name "M_MR_COXA"
            }
          ]
          endPoint Solid {
            translation 0.019947033851423223 -0.00247084176184464 1.1721242531390086e-05
            rotation -3.674754560145106e-06 -0.00020799224052782162 -0.9999999783628617 0.023574289274549916
            children [
              DEF JointCF Pose {
                translation 0.022 -1.67293e-08 -1.67294e-08
                rotation 0.5773509358554485 -0.5773509358554485 0.5773489358556708 2.0944
                children [
                  Shape {
                    appearance PBRAppearance {
                      baseColor 0.101961 0.101961 0.101961
                      roughness 1
                      metalness 0.3
                    }
                    geometry Box {
                      size 0.045 0.02 0.045
                    }
                  }
                ]
              }
              DEF R_SHAPE_COXA Shape {
                appearance PBRAppearance {
                  baseColor 0.54902 0.54902 0.54902
                  roughness 1
                  metalness 0.3
                }
                geometry Mesh {
                  url [
                    "../webotsSTL/right-coxa-webots.stl"
                  ]
                }
              }
              HingeJoint {
                jointParameters HingeJointParameters {
                  position -0.3282106953684465
                  axis 0 -1 0
                  anchor 0.0229 0 -0.0077
                }
                device [
                  RotationalMotor {
                    name "M_MR_FEMUR"
                  }
                  PositionSensor {
                    name "S_MR_FEMUR"
                  }
                ]
                endPoint Solid {
                  translation 0.0633415807784773 0 -0.013337246148416231
                  rotation -0.973657046643957 0.1612326808665309 0.16123268322880027 1.5974882542823705
                  children [
                    HingeJoint {
                      jointParameters HingeJointParameters {
                        position -0.23025430046355264
                        axis 0 0 1
                        anchor 0.041 0.008 0
                      }
                      device [
                        RotationalMotor {
                          name "M_MR_TIBIA"
                        }
                        PositionSensor {
                          name "S_MR_TIBIA"
                        }
                      ]
                      endPoint Solid {
                        translation 0.0647515421674637 0.04347308151347793 2.4767050973366033e-05
                        rotation -0.08149695172228591 -0.7047562264409875 0.7047530831097052 2.978956226929939
                        children [
                          DEF JointFT Pose {
                            translation 0.0118 0 0.035
                            rotation 0.3243588663662829 0.3243588663662829 0.888584633908982 1.68865
                            children [
                              Shape {
                                appearance PBRAppearance {
                                  baseColor 0.101961 0.101961 0.101961
                                  roughness 1
                                  metalness 0.3
                                }
                                geometry Box {
                                  size 0.045 0.02 0.045
                                }
                              }
                            ]
                          }
                          DEF R_SHAPE_TIBIA Shape {
                            appearance PBRAppearance {
                              baseColor 0.513726 0.513726 0.513726
                              roughness 1
                              metalness 0.3
                            }
                            geometry Mesh {
                              url [
                                "../webotsSTL/right-tibia-webots.stl"
                              ]
                            }
                          }
                        ]
                        boundingObject Group {
                          children [
                            Pose {
                              translation -0.033 0 -0.02
                              children [
                                Box {
                                  size 0.01 0.01 0.08
                                }
                              ]
                            }
                          ]
                        }
                        physics Physics {
                          density -1
                          mass 0.8
                        }
                        linearVelocity 9.952791934511003e-06 -1.881876749262232e-05 3.942963395784746e-06
                        angularVelocity 1.484958009883273e-05 7.521297408818397e-05 -9.791341582914626e-05
                      }
                    }
                    DEF R_SHAPE_FEMUR Shape {
                      appearance PBRAppearance {
                        baseColor 0.505882 0.505882 0.505882
                        roughness 1
                        metalness 0.3
                      }
                      geometry Mesh {
                        url [
                          "../webotsSTL/right-femur-webots.stl"
                        ]
                      }
                    }
                  ]
                  boundingObject USE R_SHAPE_FEMUR
                  physics Physics {
                    density -1
                    mass 0.8
                  }
                  linearVelocity 2.0798662698770263e-05 -2.223845510089588e-05 5.875187607560797e-06
                  angularVelocity 4.788507049577167e-05 7.29003645106327e-05 -9.831062304687463e-05
                }
              }
            ]
            boundingObject USE R_SHAPE_COXA
            physics Physics {
              density -1
              mass 0.8
            }
            linearVelocity 2.5615493913720705e-05 -2.420370562088469e-05 7.97160739707621e-06
            angularVelocity 9.06354384420616e-06 7.624298730127175e-05 -9.797469754164545e-05
          }
        }
      ]
    }
    DEF Body Pose {
      children [
        Shape {
          appearance PBRAppearance {
            baseColor 0.533333 0.533333 0.533333
            roughness 1
            metalness 0.3
          }
          geometry Mesh {
            url [
              "../webotsSTL/frame-webots.stl"
            ]
          }
        }
      ]
    }
  ]
  name "Hexapod"
  boundingObject Box {
    size 0.17 0.2 0.02
  }
  physics Physics {
    density 500
  }
  controller "new_hexapod"
  linearVelocity 2.3582643849888977e-05 -2.5014402020480597e-05 9.152881784923814e-06
  angularVelocity 8.980866184420051e-06 5.991631919918568e-05 3.2988300712049395e-05
}
