#VRML_SIM R2023b utf8

EXTERNPROTO "https://raw.githubusercontent.com/cyberbotics/webots/R2023b/projects/objects/backgrounds/protos/TexturedBackground.proto"
EXTERNPROTO "https://raw.githubusercontent.com/cyberbotics/webots/R2023b/projects/objects/backgrounds/protos/TexturedBackgroundLight.proto"
EXTERNPROTO "https://raw.githubusercontent.com/cyberbotics/webots/R2023b/projects/objects/floors/protos/RectangleArena.proto"
EXTERNPROTO "https://raw.githubusercontent.com/cyberbotics/webots/R2023b/projects/appearances/protos/Parquetry.proto"

WorldInfo {
}
Viewpoint {
  orientation 0.13424615895247458 0.1524628550765643 -0.9791491442208432 1.8421304684017683
  position 0.19575681480343665 1.1474757047207085 0.4936332391456907
  follow "Hexapod"
}
TexturedBackground {
}
RectangleArena {
  floorSize 10 10
  floorAppearance Parquetry {
    type "light strip"
  }
}
TexturedBackgroundLight {
}
Pose {
  translation -0.83 0 0
  children [
    Group {
      children [
        Solid {
          translation -0.019933880692263206 -0.039987297428865066 0.0496076
          rotation 1.865638562124743e-12 1.6063114219185855e-12 -1 5.076325663229e-05
          children [
            DEF BOX Shape {
              appearance PBRAppearance {
              }
              geometry Box {
                size 0.1 0.1 0.1
              }
            }
          ]
          boundingObject USE BOX
          physics Physics {
          }
          linearVelocity -3.0805168241675353e-17 2.390134560014339e-17 0
          angularVelocity -1.4791141972893971e-30 -5.329070518200742e-16 -2.970285586870008e-16
        }
        Solid {
          translation 0.06990678014426754 -0.19993550478438063 0.04960760000000001
          rotation -3.5048172175983426e-13 7.423512176301586e-13 0.9999999999999999 9.931916513735763e-05
          children [
            DEF BOX Shape {
              appearance PBRAppearance {
              }
              geometry Box {
                size 0.1 0.1 0.1
              }
            }
          ]
          name "solid(1)"
          boundingObject USE BOX
          physics Physics {
          }
          linearVelocity 4.103453095925552e-17 3.5774274040659085e-19 5.6843418860808e-17
          angularVelocity 2.664535259100374e-16 1.06581410364015e-15 -1.468429450847428e-16
        }
        Solid {
          translation 0.2427788537707931 -0.1300340540610465 0.04960760000000001
          rotation 9.362738357457394e-13 2.430426718799471e-14 -1 2.483653839817223e-05
          children [
            DEF BOX Shape {
              appearance PBRAppearance {
              }
              geometry Box {
                size 0.1 0.1 0.1
              }
            }
          ]
          name "solid(2)"
          boundingObject USE BOX
          physics Physics {
          }
          linearVelocity 1.4055518786149397e-17 -7.996085196082325e-17 -5.6843418860808e-17
          angularVelocity 1.3322676295501875e-15 2.6645352591003697e-16 2.209166088277317e-16
        }
        Solid {
          translation 0.24010227170996068 0.2200350097607885 0.0496076
          rotation -1.7858873391871213e-12 -8.700054399354435e-13 1 7.175482358367162e-05
          children [
            DEF BOX Shape {
              appearance PBRAppearance {
              }
              geometry Box {
                size 0.1 0.1 0.1
              }
            }
          ]
          name "solid(3)"
          boundingObject USE BOX
          physics Physics {
          }
          linearVelocity -3.180545104561023e-17 4.515556834590239e-18 -5.6843418860808e-17
          angularVelocity 5.329070518200738e-16 -2.6645352591003707e-16 -1.5786588817379345e-16
        }
        Solid {
          translation -0.020051649108723035 0.15992621635509713 0.0496076
          rotation 3.8883306227303224e-13 -1.702746594756435e-13 -0.9999999999999999 0.00017334433090604115
          children [
            DEF BOX Shape {
              appearance PBRAppearance {
              }
              geometry Box {
                size 0.1 0.1 0.1
              }
            }
          ]
          name "solid(4)"
          boundingObject USE BOX
          physics Physics {
          }
          linearVelocity 1.0713231912085764e-17 1.7301752876059054e-17 0
          angularVelocity -7.993605777301126e-16 7.99360577730113e-16 1.4865216312747852e-16
        }
        Solid {
          translation 0.23263016943535741 0.05998653481257025 0.04960760000000001
          rotation -3.3898564746011885e-12 -1.1888021094519153e-12 -1 2.8865795149786667e-05
          children [
            DEF BOX Shape {
              appearance PBRAppearance {
              }
              geometry Box {
                size 0.1 0.1 0.1
              }
            }
          ]
          name "solid(5)"
          boundingObject USE BOX
          physics Physics {
          }
          linearVelocity 1.1051225155754395e-17 -4.5426132800676195e-17 1.232595164407831e-32
          angularVelocity 7.993605777301133e-16 9.860761315262648e-32 6.338070607316566e-17
        }
      ]
    }
  ]
}
Robot {
  translation 0 0 0.107
  children [
    DEF Leg0FR Pose {
      translation 0.063 0.082 0
      rotation 0 0 1 0.785398
      children [
        DEF JointBC Pose {
          translation -0.008 0 0
          children [
            Shape {
              appearance PBRAppearance {
                baseColor 0.101961 0.101961 0.101961
                roughness 1
                metalness 0.3
              }
              geometry Box {
                size 0.045 0.02 0.045
              }
            }
          ]
        }
        HingeJoint {
          jointParameters HingeJointParameters {
            position -6.887190904425364e-08
            axis 0 0 -1
          }
          device [
            PositionSensor {
              name "S_FR_COXA"
            }
            RotationalMotor {
              name "M_FR_COXA"
            }
          ]
          endPoint Solid {
            translation 0.020000000137743775 -0.001999998622561815 0
            rotation 0 0 1 6.664001874625056e-08
            children [
              DEF JointCF Pose {
                translation 0.022 -1.67293e-08 -1.67294e-08
                rotation 0.5773509358554485 -0.5773509358554485 0.5773489358556708 2.0944
                children [
                  Shape {
                    appearance PBRAppearance {
                      baseColor 0.101961 0.101961 0.101961
                      roughness 1
                      metalness 0.3
                    }
                    geometry Box {
                      size 0.045 0.02 0.045
                    }
                  }
                ]
              }
              DEF R_SHAPE_COXA Shape {
                appearance PBRAppearance {
                  baseColor 0.54902 0.54902 0.54902
                  roughness 1
                  metalness 0.3
                }
                geometry Mesh {
                  url [
                    "../webotsSTL/right-coxa-webots.stl"
                  ]
                }
              }
              HingeJoint {
                jointParameters HingeJointParameters {
                  position 1.2687637223161715e-06
                  axis 0 -1 0
                  anchor 0.0229 0 -0.0077
                }
                device [
                  RotationalMotor {
                    name "M_FR_FEMUR"
                  }
                  PositionSensor {
                    name "S_FR_FEMUR"
                  }
                ]
                endPoint Solid {
                  translation 0.06299999023048687 0 5.087741907199711e-08
                  rotation -0.9999999999998842 -4.1487250798380817e-07 -2.436028611580823e-07 1.5707953071798104
                  children [
                    HingeJoint {
                      jointParameters HingeJointParameters {
                        position -5.865085321729384e-07
                        axis 0 0 1
                        anchor 0.041 0.008 0
                      }
                      device [
                        RotationalMotor {
                          name "M_FR_TIBIA"
                        }
                        PositionSensor {
                          name "S_FR_TIBIA"
                        }
                      ]
                      endPoint Solid {
                        translation 0.05602887585070351 0.04795757948198087 2.476705097336627e-05
                        rotation -2.0397200869453604e-07 -0.7071082811857333 0.7071052811841502 3.1415895852767193
                        children [
                          DEF JointFT Pose {
                            translation 0.0118 0 0.035
                            rotation 0.3243588663662829 0.3243588663662829 0.888584633908982 1.68865
                            children [
                              Shape {
                                appearance PBRAppearance {
                                  baseColor 0.101961 0.101961 0.101961
                                  roughness 1
                                  metalness 0.3
                                }
                                geometry Box {
                                  size 0.045 0.02 0.045
                                }
                              }
                            ]
                          }
                          DEF R_SHAPE_TIBIA Shape {
                            appearance PBRAppearance {
                              baseColor 0.513726 0.513726 0.513726
                              roughness 1
                              metalness 0.3
                            }
                            geometry Mesh {
                              url [
                                "../webotsSTL/right-tibia-webots.stl"
                              ]
                            }
                          }
                        ]
                        boundingObject Group {
                          children [
                            Pose {
                              translation -0.033 0 -0.02
                              children [
                                Box {
                                  size 0.01 0.01 0.08
                                }
                              ]
                            }
                          ]
                        }
                        physics Physics {
                          density -1
                          mass 0.8
                        }
                      }
                    }
                    DEF R_SHAPE_FEMUR Shape {
                      appearance PBRAppearance {
                        baseColor 0.505882 0.505882 0.505882
                        roughness 1
                        metalness 0.3
                      }
                      geometry Mesh {
                        url [
                          "../webotsSTL/right-femur-webots.stl"
                        ]
                      }
                    }
                  ]
                  boundingObject USE R_SHAPE_FEMUR
                  physics Physics {
                    density -1
                    mass 0.8
                  }
                }
              }
            ]
            name "solid(5)"
            boundingObject USE R_SHAPE_COXA
            physics Physics {
              density -1
              mass 0.8
            }
          }
        }
      ]
    }
    DEF Leg0BR Pose {
      translation 0.06 -0.08 0
      rotation 0 0 1 -0.785395307179586
      children [
        DEF JointBC Pose {
          translation -0.008 0 0
          children [
            Shape {
              appearance PBRAppearance {
                baseColor 0.101961 0.101961 0.101961
                roughness 1
                metalness 0.3
              }
              geometry Box {
                size 0.045 0.02 0.045
              }
            }
          ]
        }
        HingeJoint {
          jointParameters HingeJointParameters {
            position -3.678971947381412e-09
            axis 0 0 -1
          }
          device [
            PositionSensor {
              name "S_BR_COXA"
            }
            RotationalMotor {
              name "M_BR_COXA"
            }
          ]
          endPoint Solid {
            translation 0.02000000000735794 -0.0019999999264205606 0
            rotation 0 0 -1 0
            children [
              DEF JointCF Pose {
                translation 0.022 -1.67293e-08 -1.67294e-08
                rotation 0.5773509358554485 -0.5773509358554485 0.5773489358556708 2.0944
                children [
                  Shape {
                    appearance PBRAppearance {
                      baseColor 0.101961 0.101961 0.101961
                      roughness 1
                      metalness 0.3
                    }
                    geometry Box {
                      size 0.045 0.02 0.045
                    }
                  }
                ]
              }
              DEF R_SHAPE_COXA Shape {
                appearance PBRAppearance {
                  baseColor 0.54902 0.54902 0.54902
                  roughness 1
                  metalness 0.3
                }
                geometry Mesh {
                  url [
                    "../webotsSTL/right-coxa-webots.stl"
                  ]
                }
              }
              HingeJoint {
                jointParameters HingeJointParameters {
                  position 1.134154076425542e-06
                  axis 0 -1 0
                  anchor 0.0229 0 -0.0077
                }
                device [
                  RotationalMotor {
                    name "M_BR_FEMUR"
                  }
                  PositionSensor {
                    name "S_BR_FEMUR"
                  }
                ]
                endPoint Solid {
                  translation 0.06299999126698763 0 4.54795735160482e-08
                  rotation -0.999999999999924 -3.475676164134534e-07 -1.7629803821277943e-07 1.5707953071797591
                  children [
                    HingeJoint {
                      jointParameters HingeJointParameters {
                        position -5.405746093789971e-07
                        axis 0 0 1
                        anchor 0.041 0.008 0
                      }
                      device [
                        RotationalMotor {
                          name "M_BR_TIBIA"
                        }
                        PositionSensor {
                          name "S_BR_TIBIA"
                        }
                      ]
                      endPoint Solid {
                        translation 0.056028874015295126 0.04795758017231608 2.476705097336627e-05
                        rotation -1.8773188009706033e-07 -0.7071082811857203 0.7071052811841678 3.1415896177568388
                        children [
                          DEF JointFT Pose {
                            translation 0.0118 0 0.035
                            rotation 0.3243588663662829 0.3243588663662829 0.888584633908982 1.68865
                            children [
                              Shape {
                                appearance PBRAppearance {
                                  baseColor 0.101961 0.101961 0.101961
                                  roughness 1
                                  metalness 0.3
                                }
                                geometry Box {
                                  size 0.045 0.02 0.045
                                }
                              }
                            ]
                          }
                          DEF R_SHAPE_TIBIA Shape {
                            appearance PBRAppearance {
                              baseColor 0.513726 0.513726 0.513726
                              roughness 1
                              metalness 0.3
                            }
                            geometry Mesh {
                              url [
                                "../webotsSTL/right-tibia-webots.stl"
                              ]
                            }
                          }
                        ]
                        boundingObject Group {
                          children [
                            Pose {
                              translation -0.033 0 -0.02
                              children [
                                Box {
                                  size 0.01 0.01 0.08
                                }
                              ]
                            }
                          ]
                        }
                        physics Physics {
                          density -1
                          mass 0.8
                        }
                      }
                    }
                    DEF R_SHAPE_FEMUR Shape {
                      appearance PBRAppearance {
                        baseColor 0.505882 0.505882 0.505882
                        roughness 1
                        metalness 0.3
                      }
                      geometry Mesh {
                        url [
                          "../webotsSTL/right-femur-webots.stl"
                        ]
                      }
                    }
                  ]
                  boundingObject USE R_SHAPE_FEMUR
                  physics Physics {
                    density -1
                    mass 0.8
                  }
                }
              }
            ]
            name "solid(4)"
            boundingObject USE R_SHAPE_COXA
            physics Physics {
              density -1
              mass 0.8
            }
          }
        }
      ]
    }
    DEF Leg0FL Pose {
      translation -0.063 0.082 0
      rotation 0 0 1 2.3562
      children [
        DEF JointBC Pose {
          translation -0.008 0 0
          children [
            Shape {
              appearance PBRAppearance {
                baseColor 0.101961 0.101961 0.101961
                roughness 1
                metalness 0.3
              }
              geometry Box {
                size 0.045 0.02 0.045
              }
            }
          ]
        }
        HingeJoint {
          jointParameters HingeJointParameters {
            position -1.3224569011686786e-08
            axis 0 0 -1
          }
          device [
            PositionSensor {
              name "S_FL_COXA"
            }
            RotationalMotor {
              name "M_FL_COXA"
            }
          ]
          endPoint Solid {
            translation 0.020000000139610716 0.0019999986038923964 0
            rotation 0 0 -1 0
            children [
              DEF JointCF Pose {
                translation 0.022 -1.67293e-08 -1.67294e-08
                rotation 0.5773509358554485 -0.5773509358554485 0.5773489358556708 2.0944
                children [
                  Shape {
                    appearance PBRAppearance {
                      baseColor 0.101961 0.101961 0.101961
                      roughness 1
                      metalness 0.3
                    }
                    geometry Box {
                      size 0.045 0.02 0.045
                    }
                  }
                ]
              }
              DEF L_SHAPE_COXA Shape {
                appearance PBRAppearance {
                  baseColor 0.54902 0.54902 0.54902
                  roughness 1
                  metalness 0.3
                }
                geometry Mesh {
                  url [
                    "../webotsSTL/left-coxa-webots.stl"
                  ]
                }
              }
              HingeJoint {
                jointParameters HingeJointParameters {
                  position -2.3852281276898326e-06
                  axis 0 1 0
                  anchor 0.0229 0 -0.0077
                }
                device [
                  RotationalMotor {
                    name "M_FL_FEMUR"
                  }
                  PositionSensor {
                    name "S_FL_FEMUR"
                  }
                ]
                endPoint Solid {
                  translation 0.06299998163362912 0 9.564762603470056e-08
                  rotation 0.9999999999985777 -1.192609683273151e-06 1.192614063883038e-06 1.5708000000014204
                  children [
                    HingeJoint {
                      jointParameters HingeJointParameters {
                        position 1.0946431804541734e-06
                        axis 0 0 1
                        anchor 0.04 -0.0095 0
                      }
                      device [
                        RotationalMotor {
                          name "M_FL_TIBIA"
                        }
                        PositionSensor {
                          name "S_FL_TIBIA"
                        }
                      ]
                      endPoint Solid {
                        translation 0.0610000454276794 -0.05099997701246827 -8.485299999999979e-07
                        rotation -3.904050356264446e-07 0.707106281185754 0.7071072811868798 3.141590774030163
                        children [
                          DEF JointFT Pose {
                            translation 0.012 0 0.0354013
                            rotation 0.3243588663662829 0.3243588663662829 0.888584633908982 1.68865
                            children [
                              Shape {
                                appearance PBRAppearance {
                                  baseColor 0.101961 0.101961 0.101961
                                  roughness 1
                                  metalness 0.3
                                }
                                geometry Box {
                                  size 0.045 0.02 0.045
                                }
                              }
                            ]
                          }
                          DEF L_SHAPE_TIBIA Shape {
                            appearance PBRAppearance {
                              baseColor 0.513726 0.513726 0.513726
                              roughness 1
                              metalness 0.3
                            }
                            geometry Mesh {
                              url [
                                "../webotsSTL/left-tibia-webots.stl"
                              ]
                            }
                          }
                        ]
                        boundingObject Group {
                          children [
                            Pose {
                              translation -0.033 0 -0.02
                              children [
                                Box {
                                  size 0.01 0.01 0.08
                                }
                              ]
                            }
                          ]
                        }
                        physics Physics {
                          density -1
                          mass 0.8
                        }
                      }
                    }
                    DEF L_SHAPE_FEMUR Shape {
                      appearance PBRAppearance {
                        baseColor 0.505882 0.505882 0.505882
                        roughness 1
                        metalness 0.3
                      }
                      geometry Mesh {
                        url [
                          "../webotsSTL/left-femur-webots.stl"
                        ]
                      }
                    }
                  ]
                  boundingObject USE L_SHAPE_FEMUR
                  physics Physics {
                    density -1
                    mass 0.8
                  }
                }
              }
            ]
            name "solid(2)"
            boundingObject USE L_SHAPE_COXA
            physics Physics {
              density -1
              mass 0.8
            }
          }
        }
      ]
    }
    DEF Leg0BL Pose {
      translation -0.06 -0.08 0
      rotation 0 0 -1 2.35619
      children [
        DEF JointBC Pose {
          translation -0.008 0 0
          children [
            Shape {
              appearance PBRAppearance {
                baseColor 0.101961 0.101961 0.101961
                roughness 1
                metalness 0.3
              }
              geometry Box {
                size 0.045 0.02 0.045
              }
            }
          ]
        }
        HingeJoint {
          jointParameters HingeJointParameters {
            position -9.970004034239643e-10
            axis 0 0 -1
          }
          device [
            PositionSensor {
              name "S_BL_COXA"
            }
            RotationalMotor {
              name "M_BL_COXA"
            }
          ]
          endPoint Solid {
            translation 0.020000000164065838 0.0019999983593410224 0
            rotation 0 0 -1 0
            children [
              DEF JointCF Pose {
                translation 0.022 -1.67293e-08 -1.67294e-08
                rotation 0.5773509358554485 -0.5773509358554485 0.5773489358556708 2.0944
                children [
                  Shape {
                    appearance PBRAppearance {
                      baseColor 0.101961 0.101961 0.101961
                      roughness 1
                      metalness 0.3
                    }
                    geometry Box {
                      size 0.045 0.02 0.045
                    }
                  }
                ]
              }
              DEF L_SHAPE_COXA Shape {
                appearance PBRAppearance {
                  baseColor 0.54902 0.54902 0.54902
                  roughness 1
                  metalness 0.3
                }
                geometry Mesh {
                  url [
                    "../webotsSTL/left-coxa-webots.stl"
                  ]
                }
              }
              HingeJoint {
                jointParameters HingeJointParameters {
                  position -2.4911205477782397e-06
                  axis 0 1 0
                  anchor 0.0229 0 -0.0077
                }
                device [
                  RotationalMotor {
                    name "M_BL_FEMUR"
                  }
                  PositionSensor {
                    name "S_BL_FEMUR"
                  }
                ]
                endPoint Solid {
                  translation 0.06299998081824713 0 9.989391009518345e-08
                  rotation 0.9999999999984487 -1.2455556988352653e-06 1.245560273927084e-06 1.5708000000015494
                  children [
                    HingeJoint {
                      jointParameters HingeJointParameters {
                        position 1.1394336126776835e-06
                        axis 0 0 1
                        anchor 0.04 -0.0095 0
                      }
                      device [
                        RotationalMotor {
                          name "M_BL_TIBIA"
                        }
                        PositionSensor {
                          name "S_BL_TIBIA"
                        }
                      ]
                      endPoint Solid {
                        translation 0.06100004728648127 -0.050999976071867105 -8.485299999999978e-07
                        rotation -4.0624083360757294e-07 0.7071062811857346 0.7071072811868901 3.141590805701804
                        children [
                          DEF JointFT Pose {
                            translation 0.012 0 0.0354013
                            rotation 0.3243588663662829 0.3243588663662829 0.888584633908982 1.68865
                            children [
                              Shape {
                                appearance PBRAppearance {
                                  baseColor 0.101961 0.101961 0.101961
                                  roughness 1
                                  metalness 0.3
                                }
                                geometry Box {
                                  size 0.045 0.02 0.045
                                }
                              }
                            ]
                          }
                          DEF L_SHAPE_TIBIA Shape {
                            appearance PBRAppearance {
                              baseColor 0.513726 0.513726 0.513726
                              roughness 1
                              metalness 0.3
                            }
                            geometry Mesh {
                              url [
                                "../webotsSTL/left-tibia-webots.stl"
                              ]
                            }
                          }
                        ]
                        boundingObject Group {
                          children [
                            Pose {
                              translation -0.033 0 -0.02
                              children [
                                Box {
                                  size 0.01 0.01 0.08
                                }
                              ]
                            }
                          ]
                        }
                        physics Physics {
                          density -1
                          mass 0.8
                        }
                      }
                    }
                    DEF L_SHAPE_FEMUR Shape {
                      appearance PBRAppearance {
                        baseColor 0.505882 0.505882 0.505882
                        roughness 1
                        metalness 0.3
                      }
                      geometry Mesh {
                        url [
                          "../webotsSTL/left-femur-webots.stl"
                        ]
                      }
                    }
                  ]
                  boundingObject USE L_SHAPE_FEMUR
                  physics Physics {
                    density -1
                    mass 0.8
                  }
                }
              }
            ]
            name "solid(1)"
            boundingObject USE L_SHAPE_COXA
            physics Physics {
              density -1
              mass 0.8
            }
          }
        }
      ]
    }
    DEF Leg0ML Pose {
      translation -0.08 0 0
      rotation 0 0 -1 3.14159
      children [
        DEF JointBC Pose {
          translation -0.008 0 0
          children [
            Shape {
              appearance PBRAppearance {
                baseColor 0.101961 0.101961 0.101961
                roughness 1
                metalness 0.3
              }
              geometry Box {
                size 0.045 0.02 0.045
              }
            }
          ]
        }
        HingeJoint {
          jointParameters HingeJointParameters {
            position 1.6396983845086888e-06
            axis 0 0 -1
          }
          device [
            PositionSensor {
              name "S_ML_COXA"
            }
            RotationalMotor {
              name "M_ML_COXA"
            }
          ]
          endPoint Solid {
            translation 0.02000000344542699 0.0019999655454303626 0
            rotation 0 0 -1 1.639669502196229e-06
            children [
              DEF JointCF Pose {
                translation 0.022 -1.67293e-08 -1.67294e-08
                rotation 0.5773509358554485 -0.5773509358554485 0.5773489358556708 2.0944
                children [
                  Shape {
                    appearance PBRAppearance {
                      baseColor 0.101961 0.101961 0.101961
                      roughness 1
                      metalness 0.3
                    }
                    geometry Box {
                      size 0.045 0.02 0.045
                    }
                  }
                ]
              }
              DEF L_SHAPE_COXA Shape {
                appearance PBRAppearance {
                  baseColor 0.54902 0.54902 0.54902
                  roughness 1
                  metalness 0.3
                }
                geometry Mesh {
                  url [
                    "../webotsSTL/left-coxa-webots.stl"
                  ]
                }
              }
              HingeJoint {
                jointParameters HingeJointParameters {
                  position -9.223349442888213e-07
                  axis 0 1 0
                  anchor 0.0229 0 -0.0077
                }
                device [
                  RotationalMotor {
                    name "M_ML_FEMUR"
                  }
                  PositionSensor {
                    name "S_ML_FEMUR"
                  }
                ]
                endPoint Solid {
                  translation 0.06299999289800363 0 3.698562801249944e-08
                  rotation 0.9999999999997873 -4.611657783221279e-07 4.6116747218359744e-07 1.5708000000002105
                  children [
                    HingeJoint {
                      jointParameters HingeJointParameters {
                        position 5.020867148290526e-07
                        axis 0 0 1
                        anchor 0.04 -0.0095 0
                      }
                      device [
                        RotationalMotor {
                          name "M_ML_TIBIA"
                        }
                        PositionSensor {
                          name "S_ML_TIBIA"
                        }
                      ]
                      endPoint Solid {
                        translation 0.061000020836596 -0.05099998945617365 -8.485299999999976e-07
                        rotation -1.809048362260935e-07 0.7071062811859934 0.7071072811867251 3.1415903550291717
                        children [
                          DEF JointFT Pose {
                            translation 0.012 0 0.0354013
                            rotation 0.3243588663662829 0.3243588663662829 0.888584633908982 1.68865
                            children [
                              Shape {
                                appearance PBRAppearance {
                                  baseColor 0.101961 0.101961 0.101961
                                  roughness 1
                                  metalness 0.3
                                }
                                geometry Box {
                                  size 0.045 0.02 0.045
                                }
                              }
                            ]
                          }
                          DEF L_SHAPE_TIBIA Shape {
                            appearance PBRAppearance {
                              baseColor 0.513726 0.513726 0.513726
                              roughness 1
                              metalness 0.3
                            }
                            geometry Mesh {
                              url [
                                "../webotsSTL/left-tibia-webots.stl"
                              ]
                            }
                          }
                        ]
                        boundingObject Group {
                          children [
                            Pose {
                              translation -0.033 0 -0.02
                              children [
                                Box {
                                  size 0.01 0.01 0.08
                                }
                              ]
                            }
                          ]
                        }
                        physics Physics {
                          density -1
                          mass 0.8
                        }
                      }
                    }
                    DEF L_SHAPE_FEMUR Shape {
                      appearance PBRAppearance {
                        baseColor 0.505882 0.505882 0.505882
                        roughness 1
                        metalness 0.3
                      }
                      geometry Mesh {
                        url [
                          "../webotsSTL/left-femur-webots.stl"
                        ]
                      }
                    }
                  ]
                  boundingObject USE L_SHAPE_FEMUR
                  physics Physics {
                    density -1
                    mass 0.8
                  }
                }
              }
            ]
            name "solid(3)"
            boundingObject USE L_SHAPE_COXA
            physics Physics {
              density -1
              mass 0.8
            }
          }
        }
      ]
    }
    DEF Leg0MR Pose {
      translation 0.08 0 0
      children [
        DEF JointBC Pose {
          translation -0.008 0 0
          children [
            Shape {
              appearance PBRAppearance {
                baseColor 0.101961 0.101961 0.101961
                roughness 1
                metalness 0.3
              }
              geometry Box {
                size 0.045 0.02 0.045
              }
            }
          ]
        }
        HingeJoint {
          jointParameters HingeJointParameters {
            position 1.9832465644978036e-08
            axis 0 0 -1
          }
          device [
            PositionSensor {
              name "S_MR_COXA"
            }
            RotationalMotor {
              name "M_MR_COXA"
            }
          ]
          endPoint Solid {
            translation 0.019999738855418503 -0.0019999160474786525 1.1721242531390077e-05
            rotation -0.0053301586533178544 -0.9068452006994598 0.4214301500570251 5.40983984121126e-06
            children [
              DEF JointCF Pose {
                translation 0.022 -1.67293e-08 -1.67294e-08
                rotation 0.5773509358554485 -0.5773509358554485 0.5773489358556708 2.0944
                children [
                  Shape {
                    appearance PBRAppearance {
                      baseColor 0.101961 0.101961 0.101961
                      roughness 1
                      metalness 0.3
                    }
                    geometry Box {
                      size 0.045 0.02 0.045
                    }
                  }
                ]
              }
              DEF R_SHAPE_COXA Shape {
                appearance PBRAppearance {
                  baseColor 0.54902 0.54902 0.54902
                  roughness 1
                  metalness 0.3
                }
                geometry Mesh {
                  url [
                    "../webotsSTL/right-coxa-webots.stl"
                  ]
                }
              }
              HingeJoint {
                jointParameters HingeJointParameters {
                  position 2.6089209616935233e-06
                  axis 0 -1 0
                  anchor 0.0229 0 -0.0077
                }
                device [
                  RotationalMotor {
                    name "M_MR_FEMUR"
                  }
                  PositionSensor {
                    name "S_MR_FEMUR"
                  }
                ]
                endPoint Solid {
                  translation 0.06299997991117195 0 1.046177043658586e-07
                  rotation -0.9999999999989939 -1.0849518108944129e-06 -9.136814808461168e-07 1.5707953071808152
                  children [
                    HingeJoint {
                      jointParameters HingeJointParameters {
                        position -1.0779024796817115e-06
                        axis 0 0 1
                        anchor 0.041 0.008 0
                      }
                      device [
                        RotationalMotor {
                          name "M_MR_TIBIA"
                        }
                        PositionSensor {
                          name "S_MR_TIBIA"
                        }
                      ]
                      endPoint Solid {
                        translation 0.05602889548561442 0.047957572096877434 2.476705097336627e-05
                        rotation -3.77706373498635e-07 -0.7071082811858611 0.7071052811839512 3.141589237809464
                        children [
                          DEF JointFT Pose {
                            translation 0.0118 0 0.035
                            rotation 0.3243588663662829 0.3243588663662829 0.888584633908982 1.68865
                            children [
                              Shape {
                                appearance PBRAppearance {
                                  baseColor 0.101961 0.101961 0.101961
                                  roughness 1
                                  metalness 0.3
                                }
                                geometry Box {
                                  size 0.045 0.02 0.045
                                }
                              }
                            ]
                          }
                          DEF R_SHAPE_TIBIA Shape {
                            appearance PBRAppearance {
                              baseColor 0.513726 0.513726 0.513726
                              roughness 1
                              metalness 0.3
                            }
                            geometry Mesh {
                              url [
                                "../webotsSTL/right-tibia-webots.stl"
                              ]
                            }
                          }
                        ]
                        boundingObject Group {
                          children [
                            Pose {
                              translation -0.033 0 -0.02
                              children [
                                Box {
                                  size 0.01 0.01 0.08
                                }
                              ]
                            }
                          ]
                        }
                        physics Physics {
                          density -1
                          mass 0.8
                        }
                      }
                    }
                    DEF R_SHAPE_FEMUR Shape {
                      appearance PBRAppearance {
                        baseColor 0.505882 0.505882 0.505882
                        roughness 1
                        metalness 0.3
                      }
                      geometry Mesh {
                        url [
                          "../webotsSTL/right-femur-webots.stl"
                        ]
                      }
                    }
                  ]
                  boundingObject USE R_SHAPE_FEMUR
                  physics Physics {
                    density -1
                    mass 0.8
                  }
                }
              }
            ]
            boundingObject USE R_SHAPE_COXA
            physics Physics {
              density -1
              mass 0.8
            }
          }
        }
      ]
    }
    DEF Body Pose {
      children [
        Shape {
          appearance PBRAppearance {
            baseColor 0.533333 0.533333 0.533333
            roughness 1
            metalness 0.3
          }
          geometry Mesh {
            url [
              "../webotsSTL/frame-webots.stl"
            ]
          }
        }
      ]
    }
  ]
  name "Hexapod"
  boundingObject Box {
    size 0.17 0.2 0.02
  }
  physics Physics {
    density 500
  }
  controller "new_hexapod"
}
